2018-11-06 16:25:36 [287] [INFO] Starting gunicorn 17.5
2018-11-06 16:25:36 [287] [INFO] Listening at: http://0.0.0.0:8000 (287)
2018-11-06 16:25:36 [287] [INFO] Using worker: sync
2018-11-06 16:25:36 [292] [INFO] Booting worker with pid: 292
2018-11-06 16:25:36 [292] [ERROR] Exception in worker process:
Traceback (most recent call last):
  File "/usr/lib/python2.7/dist-packages/gunicorn/arbiter.py", line 473, in spawn_worker
    worker.init_process()
  File "/usr/lib/python2.7/dist-packages/gunicorn/workers/base.py", line 100, in init_process
    self.wsgi = self.app.wsgi()
  File "/usr/lib/python2.7/dist-packages/gunicorn/app/base.py", line 115, in wsgi
    self.callable = self.load()
  File "/usr/lib/python2.7/dist-packages/gunicorn/app/wsgiapp.py", line 33, in load
    return util.import_app(self.app_uri)
  File "/usr/lib/python2.7/dist-packages/gunicorn/util.py", line 362, in import_app
    __import__(module)
ImportError: No module named hello.py
Traceback (most recent call last):
  File "/usr/lib/python2.7/dist-packages/gunicorn/arbiter.py", line 473, in spawn_worker
    worker.init_process()
  File "/usr/lib/python2.7/dist-packages/gunicorn/workers/base.py", line 100, in init_process
    self.wsgi = self.app.wsgi()
  File "/usr/lib/python2.7/dist-packages/gunicorn/app/base.py", line 115, in wsgi
    self.callable = self.load()
  File "/usr/lib/python2.7/dist-packages/gunicorn/app/wsgiapp.py", line 33, in load
    return util.import_app(self.app_uri)
  File "/usr/lib/python2.7/dist-packages/gunicorn/util.py", line 362, in import_app
    __import__(module)
ImportError: No module named hello.py
2018-11-06 16:25:36 [292] [INFO] Worker exiting (pid: 292)
2018-11-06 16:25:36 [293] [INFO] Booting worker with pid: 293
2018-11-06 16:25:36 [293] [ERROR] Exception in worker process:
Traceback (most recent call last):
  File "/usr/lib/python2.7/dist-packages/gunicorn/arbiter.py", line 473, in spawn_worker
    worker.init_process()
  File "/usr/lib/python2.7/dist-packages/gunicorn/workers/base.py", line 100, in init_process
    self.wsgi = self.app.wsgi()
  File "/usr/lib/python2.7/dist-packages/gunicorn/app/base.py", line 115, in wsgi
    self.callable = self.load()
  File "/usr/lib/python2.7/dist-packages/gunicorn/app/wsgiapp.py", line 33, in load
    return util.import_app(self.app_uri)
  File "/usr/lib/python2.7/dist-packages/gunicorn/util.py", line 362, in import_app
    __import__(module)
ImportError: No module named hello.py
Traceback (most recent call last):
  File "/usr/lib/python2.7/dist-packages/gunicorn/arbiter.py", line 473, in spawn_worker
    worker.init_process()
  File "/usr/lib/python2.7/dist-packages/gunicorn/workers/base.py", line 100, in init_process
    self.wsgi = self.app.wsgi()
  File "/usr/lib/python2.7/dist-packages/gunicorn/app/base.py", line 115, in wsgi
    self.callable = self.load()
  File "/usr/lib/python2.7/dist-packages/gunicorn/app/wsgiapp.py", line 33, in load
    return util.import_app(self.app_uri)
  File "/usr/lib/python2.7/dist-packages/gunicorn/util.py", line 362, in import_app
    __import__(module)
ImportError: No module named hello.py
2018-11-06 16:25:36 [293] [INFO] Worker exiting (pid: 293)
2018-11-06 16:25:36 [294] [INFO] Booting worker with pid: 294
2018-11-06 16:25:36 [294] [ERROR] Exception in worker process:
Traceback (most recent call last):
  File "/usr/lib/python2.7/dist-packages/gunicorn/arbiter.py", line 473, in spawn_worker
    worker.init_process()
  File "/usr/lib/python2.7/dist-packages/gunicorn/workers/base.py", line 100, in init_process
    self.wsgi = self.app.wsgi()
  File "/usr/lib/python2.7/dist-packages/gunicorn/app/base.py", line 115, in wsgi
    self.callable = self.load()
  File "/usr/lib/python2.7/dist-packages/gunicorn/app/wsgiapp.py", line 33, in load
    return util.import_app(self.app_uri)
  File "/usr/lib/python2.7/dist-packages/gunicorn/util.py", line 362, in import_app
    __import__(module)
ImportError: No module named hello.py
Traceback (most recent call last):
  File "/usr/lib/python2.7/dist-packages/gunicorn/arbiter.py", line 473, in spawn_worker
    worker.init_process()
  File "/usr/lib/python2.7/dist-packages/gunicorn/workers/base.py", line 100, in init_process
    self.wsgi = self.app.wsgi()
  File "/usr/lib/python2.7/dist-packages/gunicorn/app/base.py", line 115, in wsgi
    self.callable = self.load()
  File "/usr/lib/python2.7/dist-packages/gunicorn/app/wsgiapp.py", line 33, in load
    return util.import_app(self.app_uri)
  File "/usr/lib/python2.7/dist-packages/gunicorn/util.py", line 362, in import_app
    __import__(module)
ImportError: No module named hello.py
2018-11-06 16:25:36 [294] [INFO] Worker exiting (pid: 294)
2018-11-06 16:25:36 [295] [INFO] Booting worker with pid: 295
2018-11-06 16:25:36 [296] [INFO] Booting worker with pid: 296
2018-11-06 16:25:36 [295] [ERROR] Exception in worker process:
Traceback (most recent call last):
  File "/usr/lib/python2.7/dist-packages/gunicorn/arbiter.py", line 473, in spawn_worker
    worker.init_process()
  File "/usr/lib/python2.7/dist-packages/gunicorn/workers/base.py", line 100, in init_process
    self.wsgi = self.app.wsgi()
  File "/usr/lib/python2.7/dist-packages/gunicorn/app/base.py", line 115, in wsgi
    self.callable = self.load()
  File "/usr/lib/python2.7/dist-packages/gunicorn/app/wsgiapp.py", line 33, in load
    return util.import_app(self.app_uri)
  File "/usr/lib/python2.7/dist-packages/gunicorn/util.py", line 362, in import_app
    __import__(module)
ImportError: No module named hello.py
Traceback (most recent call last):
  File "/usr/lib/python2.7/dist-packages/gunicorn/arbiter.py", line 473, in spawn_worker
    worker.init_process()
  File "/usr/lib/python2.7/dist-packages/gunicorn/workers/base.py", line 100, in init_process
    self.wsgi = self.app.wsgi()
  File "/usr/lib/python2.7/dist-packages/gunicorn/app/base.py", line 115, in wsgi
    self.callable = self.load()
  File "/usr/lib/python2.7/dist-packages/gunicorn/app/wsgiapp.py", line 33, in load
    return util.import_app(self.app_uri)
  File "/usr/lib/python2.7/dist-packages/gunicorn/util.py", line 362, in import_app
    __import__(module)
ImportError: No module named hello.py
2018-11-06 16:25:36 [295] [INFO] Worker exiting (pid: 295)
2018-11-06 16:25:36 [296] [ERROR] Exception in worker process:
Traceback (most recent call last):
  File "/usr/lib/python2.7/dist-packages/gunicorn/arbiter.py", line 473, in spawn_worker
    worker.init_process()
  File "/usr/lib/python2.7/dist-packages/gunicorn/workers/base.py", line 100, in init_process
    self.wsgi = self.app.wsgi()
  File "/usr/lib/python2.7/dist-packages/gunicorn/app/base.py", line 115, in wsgi
    self.callable = self.load()
  File "/usr/lib/python2.7/dist-packages/gunicorn/app/wsgiapp.py", line 33, in load
    return util.import_app(self.app_uri)
  File "/usr/lib/python2.7/dist-packages/gunicorn/util.py", line 362, in import_app
    __import__(module)
ImportError: No module named hello.py
Traceback (most recent call last):
  File "/usr/lib/python2.7/dist-packages/gunicorn/arbiter.py", line 473, in spawn_worker
    worker.init_process()
  File "/usr/lib/python2.7/dist-packages/gunicorn/workers/base.py", line 100, in init_process
    self.wsgi = self.app.wsgi()
  File "/usr/lib/python2.7/dist-packages/gunicorn/app/base.py", line 115, in wsgi
    self.callable = self.load()
  File "/usr/lib/python2.7/dist-packages/gunicorn/app/wsgiapp.py", line 33, in load
    return util.import_app(self.app_uri)
  File "/usr/lib/python2.7/dist-packages/gunicorn/util.py", line 362, in import_app
    __import__(module)
ImportError: No module named hello.py
2018-11-06 16:25:36 [296] [INFO] Worker exiting (pid: 296)
2018-11-06 16:25:36 [297] [INFO] Booting worker with pid: 297
2018-11-06 16:25:36 [297] [ERROR] Exception in worker process:
Traceback (most recent call last):
  File "/usr/lib/python2.7/dist-packages/gunicorn/arbiter.py", line 473, in spawn_worker
    worker.init_process()
  File "/usr/lib/python2.7/dist-packages/gunicorn/workers/base.py", line 100, in init_process
    self.wsgi = self.app.wsgi()
  File "/usr/lib/python2.7/dist-packages/gunicorn/app/base.py", line 115, in wsgi
    self.callable = self.load()
  File "/usr/lib/python2.7/dist-packages/gunicorn/app/wsgiapp.py", line 33, in load
    return util.import_app(self.app_uri)
  File "/usr/lib/python2.7/dist-packages/gunicorn/util.py", line 362, in import_app
    __import__(module)
ImportError: No module named hello.py
Traceback (most recent call last):
  File "/usr/lib/python2.7/dist-packages/gunicorn/arbiter.py", line 473, in spawn_worker
    worker.init_process()
  File "/usr/lib/python2.7/dist-packages/gunicorn/workers/base.py", line 100, in init_process
    self.wsgi = self.app.wsgi()
  File "/usr/lib/python2.7/dist-packages/gunicorn/app/base.py", line 115, in wsgi
    self.callable = self.load()
  File "/usr/lib/python2.7/dist-packages/gunicorn/app/wsgiapp.py", line 33, in load
    return util.import_app(self.app_uri)
  File "/usr/lib/python2.7/dist-packages/gunicorn/util.py", line 362, in import_app
    __import__(module)
ImportError: No module named hello.py
2018-11-06 16:25:36 [297] [INFO] Worker exiting (pid: 297)
2018-11-06 16:25:36 [298] [INFO] Booting worker with pid: 298
2018-11-06 16:25:36 [299] [INFO] Booting worker with pid: 299
2018-11-06 16:25:36 [298] [ERROR] Exception in worker process:
Traceback (most recent call last):
  File "/usr/lib/python2.7/dist-packages/gunicorn/arbiter.py", line 473, in spawn_worker
    worker.init_process()
  File "/usr/lib/python2.7/dist-packages/gunicorn/workers/base.py", line 100, in init_process
    self.wsgi = self.app.wsgi()
  File "/usr/lib/python2.7/dist-packages/gunicorn/app/base.py", line 115, in wsgi
    self.callable = self.load()
  File "/usr/lib/python2.7/dist-packages/gunicorn/app/wsgiapp.py", line 33, in load
    return util.import_app(self.app_uri)
  File "/usr/lib/python2.7/dist-packages/gunicorn/util.py", line 362, in import_app
    __import__(module)
ImportError: No module named hello.py
Traceback (most recent call last):
  File "/usr/lib/python2.7/dist-packages/gunicorn/arbiter.py", line 473, in spawn_worker
    worker.init_process()
  File "/usr/lib/python2.7/dist-packages/gunicorn/workers/base.py", line 100, in init_process
    self.wsgi = self.app.wsgi()
  File "/usr/lib/python2.7/dist-packages/gunicorn/app/base.py", line 115, in wsgi
    self.callable = self.load()
  File "/usr/lib/python2.7/dist-packages/gunicorn/app/wsgiapp.py", line 33, in load
    return util.import_app(self.app_uri)
  File "/usr/lib/python2.7/dist-packages/gunicorn/util.py", line 362, in import_app
    __import__(module)
ImportError: No module named hello.py
2018-11-06 16:25:36 [298] [INFO] Worker exiting (pid: 298)
2018-11-06 16:25:36 [299] [ERROR] Exception in worker process:
Traceback (most recent call last):
  File "/usr/lib/python2.7/dist-packages/gunicorn/arbiter.py", line 473, in spawn_worker
    worker.init_process()
  File "/usr/lib/python2.7/dist-packages/gunicorn/workers/base.py", line 100, in init_process
    self.wsgi = self.app.wsgi()
  File "/usr/lib/python2.7/dist-packages/gunicorn/app/base.py", line 115, in wsgi
    self.callable = self.load()
  File "/usr/lib/python2.7/dist-packages/gunicorn/app/wsgiapp.py", line 33, in load
    return util.import_app(self.app_uri)
  File "/usr/lib/python2.7/dist-packages/gunicorn/util.py", line 362, in import_app
    __import__(module)
ImportError: No module named hello.py
Traceback (most recent call last):
  File "/usr/lib/python2.7/dist-packages/gunicorn/arbiter.py", line 473, in spawn_worker
    worker.init_process()
  File "/usr/lib/python2.7/dist-packages/gunicorn/workers/base.py", line 100, in init_process
    self.wsgi = self.app.wsgi()
  File "/usr/lib/python2.7/dist-packages/gunicorn/app/base.py", line 115, in wsgi
    self.callable = self.load()
  File "/usr/lib/python2.7/dist-packages/gunicorn/app/wsgiapp.py", line 33, in load
    return util.import_app(self.app_uri)
  File "/usr/lib/python2.7/dist-packages/gunicorn/util.py", line 362, in import_app
    __import__(module)
ImportError: No module named hello.py
2018-11-06 16:25:36 [299] [INFO] Worker exiting (pid: 299)
2018-11-06 16:25:36 [301] [INFO] Booting worker with pid: 301
2018-11-06 16:25:36 [300] [INFO] Booting worker with pid: 300
2018-11-06 16:25:36 [301] [ERROR] Exception in worker process:
Traceback (most recent call last):
  File "/usr/lib/python2.7/dist-packages/gunicorn/arbiter.py", line 473, in spawn_worker
    worker.init_process()
  File "/usr/lib/python2.7/dist-packages/gunicorn/workers/base.py", line 100, in init_process
    self.wsgi = self.app.wsgi()
  File "/usr/lib/python2.7/dist-packages/gunicorn/app/base.py", line 115, in wsgi
    self.callable = self.load()
  File "/usr/lib/python2.7/dist-packages/gunicorn/app/wsgiapp.py", line 33, in load
    return util.import_app(self.app_uri)
  File "/usr/lib/python2.7/dist-packages/gunicorn/util.py", line 362, in import_app
    __import__(module)
ImportError: No module named hello.py
Traceback (most recent call last):
  File "/usr/lib/python2.7/dist-packages/gunicorn/arbiter.py", line 473, in spawn_worker
    worker.init_process()
  File "/usr/lib/python2.7/dist-packages/gunicorn/workers/base.py", line 100, in init_process
    self.wsgi = self.app.wsgi()
  File "/usr/lib/python2.7/dist-packages/gunicorn/app/base.py", line 115, in wsgi
    self.callable = self.load()
  File "/usr/lib/python2.7/dist-packages/gunicorn/app/wsgiapp.py", line 33, in load
    return util.import_app(self.app_uri)
  File "/usr/lib/python2.7/dist-packages/gunicorn/util.py", line 362, in import_app
    __import__(module)
ImportError: No module named hello.py
2018-11-06 16:25:36 [301] [INFO] Worker exiting (pid: 301)
2018-11-06 16:25:36 [300] [ERROR] Exception in worker process:
Traceback (most recent call last):
  File "/usr/lib/python2.7/dist-packages/gunicorn/arbiter.py", line 473, in spawn_worker
    worker.init_process()
  File "/usr/lib/python2.7/dist-packages/gunicorn/workers/base.py", line 100, in init_process
    self.wsgi = self.app.wsgi()
  File "/usr/lib/python2.7/dist-packages/gunicorn/app/base.py", line 115, in wsgi
    self.callable = self.load()
  File "/usr/lib/python2.7/dist-packages/gunicorn/app/wsgiapp.py", line 33, in load
    return util.import_app(self.app_uri)
  File "/usr/lib/python2.7/dist-packages/gunicorn/util.py", line 362, in import_app
    __import__(module)
ImportError: No module named hello.py
Traceback (most recent call last):
  File "/usr/lib/python2.7/dist-packages/gunicorn/arbiter.py", line 473, in spawn_worker
    worker.init_process()
  File "/usr/lib/python2.7/dist-packages/gunicorn/workers/base.py", line 100, in init_process
    self.wsgi = self.app.wsgi()
  File "/usr/lib/python2.7/dist-packages/gunicorn/app/base.py", line 115, in wsgi
    self.callable = self.load()
  File "/usr/lib/python2.7/dist-packages/gunicorn/app/wsgiapp.py", line 33, in load
    return util.import_app(self.app_uri)
  File "/usr/lib/python2.7/dist-packages/gunicorn/util.py", line 362, in import_app
    __import__(module)
ImportError: No module named hello.py
2018-11-06 16:25:36 [300] [INFO] Worker exiting (pid: 300)
2018-11-06 16:25:36 [302] [INFO] Booting worker with pid: 302
2018-11-06 16:25:36 [303] [INFO] Booting worker with pid: 303
2018-11-06 16:25:36 [302] [ERROR] Exception in worker process:
Traceback (most recent call last):
  File "/usr/lib/python2.7/dist-packages/gunicorn/arbiter.py", line 473, in spawn_worker
    worker.init_process()
  File "/usr/lib/python2.7/dist-packages/gunicorn/workers/base.py", line 100, in init_process
    self.wsgi = self.app.wsgi()
  File "/usr/lib/python2.7/dist-packages/gunicorn/app/base.py", line 115, in wsgi
    self.callable = self.load()
  File "/usr/lib/python2.7/dist-packages/gunicorn/app/wsgiapp.py", line 33, in load
    return util.import_app(self.app_uri)
  File "/usr/lib/python2.7/dist-packages/gunicorn/util.py", line 362, in import_app
    __import__(module)
ImportError: No module named hello.py
Traceback (most recent call last):
  File "/usr/lib/python2.7/dist-packages/gunicorn/arbiter.py", line 473, in spawn_worker
    worker.init_process()
  File "/usr/lib/python2.7/dist-packages/gunicorn/workers/base.py", line 100, in init_process
    self.wsgi = self.app.wsgi()
  File "/usr/lib/python2.7/dist-packages/gunicorn/app/base.py", line 115, in wsgi
    self.callable = self.load()
  File "/usr/lib/python2.7/dist-packages/gunicorn/app/wsgiapp.py", line 33, in load
    return util.import_app(self.app_uri)
  File "/usr/lib/python2.7/dist-packages/gunicorn/util.py", line 362, in import_app
    __import__(module)
ImportError: No module named hello.py
2018-11-06 16:25:36 [302] [INFO] Worker exiting (pid: 302)
2018-11-06 16:25:36 [303] [ERROR] Exception in worker process:
Traceback (most recent call last):
  File "/usr/lib/python2.7/dist-packages/gunicorn/arbiter.py", line 473, in spawn_worker
    worker.init_process()
  File "/usr/lib/python2.7/dist-packages/gunicorn/workers/base.py", line 100, in init_process
    self.wsgi = self.app.wsgi()
  File "/usr/lib/python2.7/dist-packages/gunicorn/app/base.py", line 115, in wsgi
    self.callable = self.load()
  File "/usr/lib/python2.7/dist-packages/gunicorn/app/wsgiapp.py", line 33, in load
    return util.import_app(self.app_uri)
  File "/usr/lib/python2.7/dist-packages/gunicorn/util.py", line 362, in import_app
    __import__(module)
ImportError: No module named hello.py
Traceback (most recent call last):
  File "/usr/lib/python2.7/dist-packages/gunicorn/arbiter.py", line 473, in spawn_worker
    worker.init_process()
  File "/usr/lib/python2.7/dist-packages/gunicorn/workers/base.py", line 100, in init_process
    self.wsgi = self.app.wsgi()
  File "/usr/lib/python2.7/dist-packages/gunicorn/app/base.py", line 115, in wsgi
    self.callable = self.load()
  File "/usr/lib/python2.7/dist-packages/gunicorn/app/wsgiapp.py", line 33, in load
    return util.import_app(self.app_uri)
  File "/usr/lib/python2.7/dist-packages/gunicorn/util.py", line 362, in import_app
    __import__(module)
ImportError: No module named hello.py
2018-11-06 16:25:36 [303] [INFO] Worker exiting (pid: 303)
2018-11-06 16:25:36 [304] [INFO] Booting worker with pid: 304
2018-11-06 16:25:36 [304] [ERROR] Exception in worker process:
Traceback (most recent call last):
  File "/usr/lib/python2.7/dist-packages/gunicorn/arbiter.py", line 473, in spawn_worker
    worker.init_process()
  File "/usr/lib/python2.7/dist-packages/gunicorn/workers/base.py", line 100, in init_process
    self.wsgi = self.app.wsgi()
  File "/usr/lib/python2.7/dist-packages/gunicorn/app/base.py", line 115, in wsgi
    self.callable = self.load()
  File "/usr/lib/python2.7/dist-packages/gunicorn/app/wsgiapp.py", line 33, in load
    return util.import_app(self.app_uri)
  File "/usr/lib/python2.7/dist-packages/gunicorn/util.py", line 362, in import_app
    __import__(module)
ImportError: No module named hello.py
Traceback (most recent call last):
  File "/usr/lib/python2.7/dist-packages/gunicorn/arbiter.py", line 473, in spawn_worker
    worker.init_process()
  File "/usr/lib/python2.7/dist-packages/gunicorn/workers/base.py", line 100, in init_process
    self.wsgi = self.app.wsgi()
  File "/usr/lib/python2.7/dist-packages/gunicorn/app/base.py", line 115, in wsgi
    self.callable = self.load()
  File "/usr/lib/python2.7/dist-packages/gunicorn/app/wsgiapp.py", line 33, in load
    return util.import_app(self.app_uri)
  File "/usr/lib/python2.7/dist-packages/gunicorn/util.py", line 362, in import_app
    __import__(module)
ImportError: No module named hello.py
2018-11-06 16:25:36 [304] [INFO] Worker exiting (pid: 304)
2018-11-06 16:25:36 [305] [INFO] Booting worker with pid: 305
2018-11-06 16:25:36 [306] [INFO] Booting worker with pid: 306
2018-11-06 16:25:36 [306] [ERROR] Exception in worker process:
Traceback (most recent call last):
  File "/usr/lib/python2.7/dist-packages/gunicorn/arbiter.py", line 473, in spawn_worker
    worker.init_process()
  File "/usr/lib/python2.7/dist-packages/gunicorn/workers/base.py", line 100, in init_process
    self.wsgi = self.app.wsgi()
  File "/usr/lib/python2.7/dist-packages/gunicorn/app/base.py", line 115, in wsgi
    self.callable = self.load()
  File "/usr/lib/python2.7/dist-packages/gunicorn/app/wsgiapp.py", line 33, in load
    return util.import_app(self.app_uri)
  File "/usr/lib/python2.7/dist-packages/gunicorn/util.py", line 362, in import_app
    __import__(module)
ImportError: No module named hello.py
Traceback (most recent call last):
  File "/usr/lib/python2.7/dist-packages/gunicorn/arbiter.py", line 473, in spawn_worker
    worker.init_process()
  File "/usr/lib/python2.7/dist-packages/gunicorn/workers/base.py", line 100, in init_process
    self.wsgi = self.app.wsgi()
  File "/usr/lib/python2.7/dist-packages/gunicorn/app/base.py", line 115, in wsgi
    self.callable = self.load()
  File "/usr/lib/python2.7/dist-packages/gunicorn/app/wsgiapp.py", line 33, in load
    return util.import_app(self.app_uri)
  File "/usr/lib/python2.7/dist-packages/gunicorn/util.py", line 362, in import_app
    __import__(module)
ImportError: No module named hello.py
2018-11-06 16:25:36 [306] [INFO] Worker exiting (pid: 306)
2018-11-06 16:25:36 [305] [ERROR] Exception in worker process:
Traceback (most recent call last):
  File "/usr/lib/python2.7/dist-packages/gunicorn/arbiter.py", line 473, in spawn_worker
    worker.init_process()
  File "/usr/lib/python2.7/dist-packages/gunicorn/workers/base.py", line 100, in init_process
    self.wsgi = self.app.wsgi()
  File "/usr/lib/python2.7/dist-packages/gunicorn/app/base.py", line 115, in wsgi
    self.callable = self.load()
  File "/usr/lib/python2.7/dist-packages/gunicorn/app/wsgiapp.py", line 33, in load
    return util.import_app(self.app_uri)
  File "/usr/lib/python2.7/dist-packages/gunicorn/util.py", line 362, in import_app
    __import__(module)
ImportError: No module named hello.py
Traceback (most recent call last):
  File "/usr/lib/python2.7/dist-packages/gunicorn/arbiter.py", line 473, in spawn_worker
    worker.init_process()
  File "/usr/lib/python2.7/dist-packages/gunicorn/workers/base.py", line 100, in init_process
    self.wsgi = self.app.wsgi()
  File "/usr/lib/python2.7/dist-packages/gunicorn/app/base.py", line 115, in wsgi
    self.callable = self.load()
  File "/usr/lib/python2.7/dist-packages/gunicorn/app/wsgiapp.py", line 33, in load
    return util.import_app(self.app_uri)
  File "/usr/lib/python2.7/dist-packages/gunicorn/util.py", line 362, in import_app
    __import__(module)
ImportError: No module named hello.py
2018-11-06 16:25:36 [305] [INFO] Worker exiting (pid: 305)
2018-11-06 16:25:36 [307] [INFO] Booting worker with pid: 307
2018-11-06 16:25:36 [307] [ERROR] Exception in worker process:
Traceback (most recent call last):
  File "/usr/lib/python2.7/dist-packages/gunicorn/arbiter.py", line 473, in spawn_worker
    worker.init_process()
  File "/usr/lib/python2.7/dist-packages/gunicorn/workers/base.py", line 100, in init_process
    self.wsgi = self.app.wsgi()
  File "/usr/lib/python2.7/dist-packages/gunicorn/app/base.py", line 115, in wsgi
    self.callable = self.load()
  File "/usr/lib/python2.7/dist-packages/gunicorn/app/wsgiapp.py", line 33, in load
    return util.import_app(self.app_uri)
  File "/usr/lib/python2.7/dist-packages/gunicorn/util.py", line 362, in import_app
    __import__(module)
ImportError: No module named hello.py
Traceback (most recent call last):
  File "/usr/lib/python2.7/dist-packages/gunicorn/arbiter.py", line 473, in spawn_worker
    worker.init_process()
  File "/usr/lib/python2.7/dist-packages/gunicorn/workers/base.py", line 100, in init_process
    self.wsgi = self.app.wsgi()
  File "/usr/lib/python2.7/dist-packages/gunicorn/app/base.py", line 115, in wsgi
    self.callable = self.load()
  File "/usr/lib/python2.7/dist-packages/gunicorn/app/wsgiapp.py", line 33, in load
    return util.import_app(self.app_uri)
  File "/usr/lib/python2.7/dist-packages/gunicorn/util.py", line 362, in import_app
    __import__(module)
ImportError: No module named hello.py
2018-11-06 16:25:36 [307] [INFO] Worker exiting (pid: 307)
Traceback (most recent call last):
  File "/usr/bin/gunicorn", line 9, in <module>
    load_entry_point('gunicorn==17.5', 'console_scripts', 'gunicorn')()
  File "/usr/lib/python2.7/dist-packages/gunicorn/app/wsgiapp.py", line 42, in run
    WSGIApplication("%(prog)s [OPTIONS] APP_MODULE").run()
  File "/usr/lib/python2.7/dist-packages/gunicorn/app/base.py", line 144, in run
    Arbiter(self).run()
  File "/usr/lib/python2.7/dist-packages/gunicorn/arbiter.py", line 196, in run
    self.halt(reason=inst.reason, exit_status=inst.exit_status)
  File "/usr/lib/python2.7/dist-packages/gunicorn/arbiter.py", line 291, in halt
    self.stop()
  File "/usr/lib/python2.7/dist-packages/gunicorn/arbiter.py", line 334, in stop
    self.reap_workers()
  File "/usr/lib/python2.7/dist-packages/gunicorn/arbiter.py", line 430, in reap_workers
    raise HaltServer(reason, self.WORKER_BOOT_ERROR)
gunicorn.errors.HaltServer: <HaltServer 'Worker failed to boot.' 3>
2018-11-06 16:34:11 [431] [INFO] Starting gunicorn 17.5
2018-11-06 16:34:11 [431] [INFO] Listening at: http://0.0.0.0:8000 (431)
2018-11-06 16:34:11 [431] [INFO] Using worker: sync
2018-11-06 16:34:11 [436] [INFO] Booting worker with pid: 436
2018-11-06 16:34:11 [436] [ERROR] Exception in worker process:
Traceback (most recent call last):
  File "/usr/lib/python2.7/dist-packages/gunicorn/arbiter.py", line 473, in spawn_worker
    worker.init_process()
  File "/usr/lib/python2.7/dist-packages/gunicorn/workers/base.py", line 100, in init_process
    self.wsgi = self.app.wsgi()
  File "/usr/lib/python2.7/dist-packages/gunicorn/app/base.py", line 115, in wsgi
    self.callable = self.load()
  File "/usr/lib/python2.7/dist-packages/gunicorn/app/wsgiapp.py", line 33, in load
    return util.import_app(self.app_uri)
  File "/usr/lib/python2.7/dist-packages/gunicorn/util.py", line 362, in import_app
    __import__(module)
ImportError: No module named hello.py
Traceback (most recent call last):
  File "/usr/lib/python2.7/dist-packages/gunicorn/arbiter.py", line 473, in spawn_worker
    worker.init_process()
  File "/usr/lib/python2.7/dist-packages/gunicorn/workers/base.py", line 100, in init_process
    self.wsgi = self.app.wsgi()
  File "/usr/lib/python2.7/dist-packages/gunicorn/app/base.py", line 115, in wsgi
    self.callable = self.load()
  File "/usr/lib/python2.7/dist-packages/gunicorn/app/wsgiapp.py", line 33, in load
    return util.import_app(self.app_uri)
  File "/usr/lib/python2.7/dist-packages/gunicorn/util.py", line 362, in import_app
    __import__(module)
ImportError: No module named hello.py
2018-11-06 16:34:11 [436] [INFO] Worker exiting (pid: 436)
2018-11-06 16:34:11 [437] [INFO] Booting worker with pid: 437
2018-11-06 16:34:11 [437] [ERROR] Exception in worker process:
Traceback (most recent call last):
  File "/usr/lib/python2.7/dist-packages/gunicorn/arbiter.py", line 473, in spawn_worker
    worker.init_process()
  File "/usr/lib/python2.7/dist-packages/gunicorn/workers/base.py", line 100, in init_process
    self.wsgi = self.app.wsgi()
  File "/usr/lib/python2.7/dist-packages/gunicorn/app/base.py", line 115, in wsgi
    self.callable = self.load()
  File "/usr/lib/python2.7/dist-packages/gunicorn/app/wsgiapp.py", line 33, in load
    return util.import_app(self.app_uri)
  File "/usr/lib/python2.7/dist-packages/gunicorn/util.py", line 362, in import_app
    __import__(module)
ImportError: No module named hello.py
Traceback (most recent call last):
  File "/usr/lib/python2.7/dist-packages/gunicorn/arbiter.py", line 473, in spawn_worker
    worker.init_process()
  File "/usr/lib/python2.7/dist-packages/gunicorn/workers/base.py", line 100, in init_process
    self.wsgi = self.app.wsgi()
  File "/usr/lib/python2.7/dist-packages/gunicorn/app/base.py", line 115, in wsgi
    self.callable = self.load()
  File "/usr/lib/python2.7/dist-packages/gunicorn/app/wsgiapp.py", line 33, in load
    return util.import_app(self.app_uri)
  File "/usr/lib/python2.7/dist-packages/gunicorn/util.py", line 362, in import_app
    __import__(module)
ImportError: No module named hello.py
2018-11-06 16:34:11 [437] [INFO] Worker exiting (pid: 437)
2018-11-06 16:34:11 [438] [INFO] Booting worker with pid: 438
2018-11-06 16:34:11 [438] [ERROR] Exception in worker process:
Traceback (most recent call last):
  File "/usr/lib/python2.7/dist-packages/gunicorn/arbiter.py", line 473, in spawn_worker
    worker.init_process()
  File "/usr/lib/python2.7/dist-packages/gunicorn/workers/base.py", line 100, in init_process
    self.wsgi = self.app.wsgi()
  File "/usr/lib/python2.7/dist-packages/gunicorn/app/base.py", line 115, in wsgi
    self.callable = self.load()
  File "/usr/lib/python2.7/dist-packages/gunicorn/app/wsgiapp.py", line 33, in load
    return util.import_app(self.app_uri)
  File "/usr/lib/python2.7/dist-packages/gunicorn/util.py", line 362, in import_app
    __import__(module)
ImportError: No module named hello.py
Traceback (most recent call last):
  File "/usr/lib/python2.7/dist-packages/gunicorn/arbiter.py", line 473, in spawn_worker
    worker.init_process()
  File "/usr/lib/python2.7/dist-packages/gunicorn/workers/base.py", line 100, in init_process
    self.wsgi = self.app.wsgi()
  File "/usr/lib/python2.7/dist-packages/gunicorn/app/base.py", line 115, in wsgi
    self.callable = self.load()
  File "/usr/lib/python2.7/dist-packages/gunicorn/app/wsgiapp.py", line 33, in load
    return util.import_app(self.app_uri)
  File "/usr/lib/python2.7/dist-packages/gunicorn/util.py", line 362, in import_app
    __import__(module)
ImportError: No module named hello.py
2018-11-06 16:34:11 [438] [INFO] Worker exiting (pid: 438)
2018-11-06 16:34:11 [439] [INFO] Booting worker with pid: 439
2018-11-06 16:34:11 [439] [ERROR] Exception in worker process:
Traceback (most recent call last):
  File "/usr/lib/python2.7/dist-packages/gunicorn/arbiter.py", line 473, in spawn_worker
    worker.init_process()
  File "/usr/lib/python2.7/dist-packages/gunicorn/workers/base.py", line 100, in init_process
    self.wsgi = self.app.wsgi()
  File "/usr/lib/python2.7/dist-packages/gunicorn/app/base.py", line 115, in wsgi
    self.callable = self.load()
  File "/usr/lib/python2.7/dist-packages/gunicorn/app/wsgiapp.py", line 33, in load
    return util.import_app(self.app_uri)
  File "/usr/lib/python2.7/dist-packages/gunicorn/util.py", line 362, in import_app
    __import__(module)
ImportError: No module named hello.py
Traceback (most recent call last):
  File "/usr/lib/python2.7/dist-packages/gunicorn/arbiter.py", line 473, in spawn_worker
    worker.init_process()
  File "/usr/lib/python2.7/dist-packages/gunicorn/workers/base.py", line 100, in init_process
    self.wsgi = self.app.wsgi()
  File "/usr/lib/python2.7/dist-packages/gunicorn/app/base.py", line 115, in wsgi
    self.callable = self.load()
  File "/usr/lib/python2.7/dist-packages/gunicorn/app/wsgiapp.py", line 33, in load
    return util.import_app(self.app_uri)
  File "/usr/lib/python2.7/dist-packages/gunicorn/util.py", line 362, in import_app
    __import__(module)
ImportError: No module named hello.py
2018-11-06 16:34:11 [439] [INFO] Worker exiting (pid: 439)
2018-11-06 16:34:11 [440] [INFO] Booting worker with pid: 440
2018-11-06 16:34:11 [440] [ERROR] Exception in worker process:
Traceback (most recent call last):
  File "/usr/lib/python2.7/dist-packages/gunicorn/arbiter.py", line 473, in spawn_worker
    worker.init_process()
  File "/usr/lib/python2.7/dist-packages/gunicorn/workers/base.py", line 100, in init_process
    self.wsgi = self.app.wsgi()
  File "/usr/lib/python2.7/dist-packages/gunicorn/app/base.py", line 115, in wsgi
    self.callable = self.load()
  File "/usr/lib/python2.7/dist-packages/gunicorn/app/wsgiapp.py", line 33, in load
    return util.import_app(self.app_uri)
  File "/usr/lib/python2.7/dist-packages/gunicorn/util.py", line 362, in import_app
    __import__(module)
ImportError: No module named hello.py
Traceback (most recent call last):
  File "/usr/lib/python2.7/dist-packages/gunicorn/arbiter.py", line 473, in spawn_worker
    worker.init_process()
  File "/usr/lib/python2.7/dist-packages/gunicorn/workers/base.py", line 100, in init_process
    self.wsgi = self.app.wsgi()
  File "/usr/lib/python2.7/dist-packages/gunicorn/app/base.py", line 115, in wsgi
    self.callable = self.load()
  File "/usr/lib/python2.7/dist-packages/gunicorn/app/wsgiapp.py", line 33, in load
    return util.import_app(self.app_uri)
  File "/usr/lib/python2.7/dist-packages/gunicorn/util.py", line 362, in import_app
    __import__(module)
ImportError: No module named hello.py
2018-11-06 16:34:11 [440] [INFO] Worker exiting (pid: 440)
2018-11-06 16:34:11 [441] [INFO] Booting worker with pid: 441
2018-11-06 16:34:11 [441] [ERROR] Exception in worker process:
Traceback (most recent call last):
  File "/usr/lib/python2.7/dist-packages/gunicorn/arbiter.py", line 473, in spawn_worker
    worker.init_process()
  File "/usr/lib/python2.7/dist-packages/gunicorn/workers/base.py", line 100, in init_process
    self.wsgi = self.app.wsgi()
  File "/usr/lib/python2.7/dist-packages/gunicorn/app/base.py", line 115, in wsgi
    self.callable = self.load()
  File "/usr/lib/python2.7/dist-packages/gunicorn/app/wsgiapp.py", line 33, in load
    return util.import_app(self.app_uri)
  File "/usr/lib/python2.7/dist-packages/gunicorn/util.py", line 362, in import_app
    __import__(module)
ImportError: No module named hello.py
Traceback (most recent call last):
  File "/usr/lib/python2.7/dist-packages/gunicorn/arbiter.py", line 473, in spawn_worker
    worker.init_process()
  File "/usr/lib/python2.7/dist-packages/gunicorn/workers/base.py", line 100, in init_process
    self.wsgi = self.app.wsgi()
  File "/usr/lib/python2.7/dist-packages/gunicorn/app/base.py", line 115, in wsgi
    self.callable = self.load()
  File "/usr/lib/python2.7/dist-packages/gunicorn/app/wsgiapp.py", line 33, in load
    return util.import_app(self.app_uri)
  File "/usr/lib/python2.7/dist-packages/gunicorn/util.py", line 362, in import_app
    __import__(module)
ImportError: No module named hello.py
2018-11-06 16:34:11 [441] [INFO] Worker exiting (pid: 441)
2018-11-06 16:34:11 [442] [INFO] Booting worker with pid: 442
2018-11-06 16:34:11 [442] [ERROR] Exception in worker process:
Traceback (most recent call last):
  File "/usr/lib/python2.7/dist-packages/gunicorn/arbiter.py", line 473, in spawn_worker
    worker.init_process()
  File "/usr/lib/python2.7/dist-packages/gunicorn/workers/base.py", line 100, in init_process
    self.wsgi = self.app.wsgi()
  File "/usr/lib/python2.7/dist-packages/gunicorn/app/base.py", line 115, in wsgi
    self.callable = self.load()
  File "/usr/lib/python2.7/dist-packages/gunicorn/app/wsgiapp.py", line 33, in load
    return util.import_app(self.app_uri)
  File "/usr/lib/python2.7/dist-packages/gunicorn/util.py", line 362, in import_app
    __import__(module)
ImportError: No module named hello.py
Traceback (most recent call last):
  File "/usr/lib/python2.7/dist-packages/gunicorn/arbiter.py", line 473, in spawn_worker
    worker.init_process()
  File "/usr/lib/python2.7/dist-packages/gunicorn/workers/base.py", line 100, in init_process
    self.wsgi = self.app.wsgi()
  File "/usr/lib/python2.7/dist-packages/gunicorn/app/base.py", line 115, in wsgi
    self.callable = self.load()
  File "/usr/lib/python2.7/dist-packages/gunicorn/app/wsgiapp.py", line 33, in load
    return util.import_app(self.app_uri)
  File "/usr/lib/python2.7/dist-packages/gunicorn/util.py", line 362, in import_app
    __import__(module)
ImportError: No module named hello.py
2018-11-06 16:34:11 [442] [INFO] Worker exiting (pid: 442)
2018-11-06 16:34:11 [443] [INFO] Booting worker with pid: 443
2018-11-06 16:34:11 [443] [ERROR] Exception in worker process:
Traceback (most recent call last):
  File "/usr/lib/python2.7/dist-packages/gunicorn/arbiter.py", line 473, in spawn_worker
    worker.init_process()
  File "/usr/lib/python2.7/dist-packages/gunicorn/workers/base.py", line 100, in init_process
    self.wsgi = self.app.wsgi()
  File "/usr/lib/python2.7/dist-packages/gunicorn/app/base.py", line 115, in wsgi
    self.callable = self.load()
  File "/usr/lib/python2.7/dist-packages/gunicorn/app/wsgiapp.py", line 33, in load
    return util.import_app(self.app_uri)
  File "/usr/lib/python2.7/dist-packages/gunicorn/util.py", line 362, in import_app
    __import__(module)
ImportError: No module named hello.py
Traceback (most recent call last):
  File "/usr/lib/python2.7/dist-packages/gunicorn/arbiter.py", line 473, in spawn_worker
    worker.init_process()
  File "/usr/lib/python2.7/dist-packages/gunicorn/workers/base.py", line 100, in init_process
    self.wsgi = self.app.wsgi()
  File "/usr/lib/python2.7/dist-packages/gunicorn/app/base.py", line 115, in wsgi
    self.callable = self.load()
  File "/usr/lib/python2.7/dist-packages/gunicorn/app/wsgiapp.py", line 33, in load
    return util.import_app(self.app_uri)
  File "/usr/lib/python2.7/dist-packages/gunicorn/util.py", line 362, in import_app
    __import__(module)
ImportError: No module named hello.py
2018-11-06 16:34:11 [443] [INFO] Worker exiting (pid: 443)
2018-11-06 16:34:11 [444] [INFO] Booting worker with pid: 444
2018-11-06 16:34:11 [444] [ERROR] Exception in worker process:
Traceback (most recent call last):
  File "/usr/lib/python2.7/dist-packages/gunicorn/arbiter.py", line 473, in spawn_worker
    worker.init_process()
  File "/usr/lib/python2.7/dist-packages/gunicorn/workers/base.py", line 100, in init_process
    self.wsgi = self.app.wsgi()
  File "/usr/lib/python2.7/dist-packages/gunicorn/app/base.py", line 115, in wsgi
    self.callable = self.load()
  File "/usr/lib/python2.7/dist-packages/gunicorn/app/wsgiapp.py", line 33, in load
    return util.import_app(self.app_uri)
  File "/usr/lib/python2.7/dist-packages/gunicorn/util.py", line 362, in import_app
    __import__(module)
ImportError: No module named hello.py
Traceback (most recent call last):
  File "/usr/lib/python2.7/dist-packages/gunicorn/arbiter.py", line 473, in spawn_worker
    worker.init_process()
  File "/usr/lib/python2.7/dist-packages/gunicorn/workers/base.py", line 100, in init_process
    self.wsgi = self.app.wsgi()
  File "/usr/lib/python2.7/dist-packages/gunicorn/app/base.py", line 115, in wsgi
    self.callable = self.load()
  File "/usr/lib/python2.7/dist-packages/gunicorn/app/wsgiapp.py", line 33, in load
    return util.import_app(self.app_uri)
  File "/usr/lib/python2.7/dist-packages/gunicorn/util.py", line 362, in import_app
    __import__(module)
ImportError: No module named hello.py
2018-11-06 16:34:11 [444] [INFO] Worker exiting (pid: 444)
2018-11-06 16:34:11 [445] [INFO] Booting worker with pid: 445
2018-11-06 16:34:11 [445] [ERROR] Exception in worker process:
Traceback (most recent call last):
  File "/usr/lib/python2.7/dist-packages/gunicorn/arbiter.py", line 473, in spawn_worker
    worker.init_process()
  File "/usr/lib/python2.7/dist-packages/gunicorn/workers/base.py", line 100, in init_process
    self.wsgi = self.app.wsgi()
  File "/usr/lib/python2.7/dist-packages/gunicorn/app/base.py", line 115, in wsgi
    self.callable = self.load()
  File "/usr/lib/python2.7/dist-packages/gunicorn/app/wsgiapp.py", line 33, in load
    return util.import_app(self.app_uri)
  File "/usr/lib/python2.7/dist-packages/gunicorn/util.py", line 362, in import_app
    __import__(module)
ImportError: No module named hello.py
Traceback (most recent call last):
  File "/usr/lib/python2.7/dist-packages/gunicorn/arbiter.py", line 473, in spawn_worker
    worker.init_process()
  File "/usr/lib/python2.7/dist-packages/gunicorn/workers/base.py", line 100, in init_process
    self.wsgi = self.app.wsgi()
  File "/usr/lib/python2.7/dist-packages/gunicorn/app/base.py", line 115, in wsgi
    self.callable = self.load()
  File "/usr/lib/python2.7/dist-packages/gunicorn/app/wsgiapp.py", line 33, in load
    return util.import_app(self.app_uri)
  File "/usr/lib/python2.7/dist-packages/gunicorn/util.py", line 362, in import_app
    __import__(module)
ImportError: No module named hello.py
2018-11-06 16:34:11 [445] [INFO] Worker exiting (pid: 445)
2018-11-06 16:34:11 [446] [INFO] Booting worker with pid: 446
2018-11-06 16:34:11 [446] [ERROR] Exception in worker process:
Traceback (most recent call last):
  File "/usr/lib/python2.7/dist-packages/gunicorn/arbiter.py", line 473, in spawn_worker
    worker.init_process()
  File "/usr/lib/python2.7/dist-packages/gunicorn/workers/base.py", line 100, in init_process
    self.wsgi = self.app.wsgi()
  File "/usr/lib/python2.7/dist-packages/gunicorn/app/base.py", line 115, in wsgi
    self.callable = self.load()
  File "/usr/lib/python2.7/dist-packages/gunicorn/app/wsgiapp.py", line 33, in load
    return util.import_app(self.app_uri)
  File "/usr/lib/python2.7/dist-packages/gunicorn/util.py", line 362, in import_app
    __import__(module)
ImportError: No module named hello.py
Traceback (most recent call last):
  File "/usr/lib/python2.7/dist-packages/gunicorn/arbiter.py", line 473, in spawn_worker
    worker.init_process()
  File "/usr/lib/python2.7/dist-packages/gunicorn/workers/base.py", line 100, in init_process
    self.wsgi = self.app.wsgi()
  File "/usr/lib/python2.7/dist-packages/gunicorn/app/base.py", line 115, in wsgi
    self.callable = self.load()
  File "/usr/lib/python2.7/dist-packages/gunicorn/app/wsgiapp.py", line 33, in load
    return util.import_app(self.app_uri)
  File "/usr/lib/python2.7/dist-packages/gunicorn/util.py", line 362, in import_app
    __import__(module)
ImportError: No module named hello.py
2018-11-06 16:34:11 [446] [INFO] Worker exiting (pid: 446)
2018-11-06 16:34:11 [447] [INFO] Booting worker with pid: 447
2018-11-06 16:34:11 [447] [ERROR] Exception in worker process:
Traceback (most recent call last):
  File "/usr/lib/python2.7/dist-packages/gunicorn/arbiter.py", line 473, in spawn_worker
    worker.init_process()
  File "/usr/lib/python2.7/dist-packages/gunicorn/workers/base.py", line 100, in init_process
    self.wsgi = self.app.wsgi()
  File "/usr/lib/python2.7/dist-packages/gunicorn/app/base.py", line 115, in wsgi
    self.callable = self.load()
  File "/usr/lib/python2.7/dist-packages/gunicorn/app/wsgiapp.py", line 33, in load
    return util.import_app(self.app_uri)
  File "/usr/lib/python2.7/dist-packages/gunicorn/util.py", line 362, in import_app
    __import__(module)
ImportError: No module named hello.py
Traceback (most recent call last):
  File "/usr/lib/python2.7/dist-packages/gunicorn/arbiter.py", line 473, in spawn_worker
    worker.init_process()
  File "/usr/lib/python2.7/dist-packages/gunicorn/workers/base.py", line 100, in init_process
    self.wsgi = self.app.wsgi()
  File "/usr/lib/python2.7/dist-packages/gunicorn/app/base.py", line 115, in wsgi
    self.callable = self.load()
  File "/usr/lib/python2.7/dist-packages/gunicorn/app/wsgiapp.py", line 33, in load
    return util.import_app(self.app_uri)
  File "/usr/lib/python2.7/dist-packages/gunicorn/util.py", line 362, in import_app
    __import__(module)
ImportError: No module named hello.py
2018-11-06 16:34:11 [447] [INFO] Worker exiting (pid: 447)
2018-11-06 16:34:11 [448] [INFO] Booting worker with pid: 448
2018-11-06 16:34:11 [448] [ERROR] Exception in worker process:
Traceback (most recent call last):
  File "/usr/lib/python2.7/dist-packages/gunicorn/arbiter.py", line 473, in spawn_worker
    worker.init_process()
  File "/usr/lib/python2.7/dist-packages/gunicorn/workers/base.py", line 100, in init_process
    self.wsgi = self.app.wsgi()
  File "/usr/lib/python2.7/dist-packages/gunicorn/app/base.py", line 115, in wsgi
    self.callable = self.load()
  File "/usr/lib/python2.7/dist-packages/gunicorn/app/wsgiapp.py", line 33, in load
    return util.import_app(self.app_uri)
  File "/usr/lib/python2.7/dist-packages/gunicorn/util.py", line 362, in import_app
    __import__(module)
ImportError: No module named hello.py
Traceback (most recent call last):
  File "/usr/lib/python2.7/dist-packages/gunicorn/arbiter.py", line 473, in spawn_worker
    worker.init_process()
  File "/usr/lib/python2.7/dist-packages/gunicorn/workers/base.py", line 100, in init_process
    self.wsgi = self.app.wsgi()
  File "/usr/lib/python2.7/dist-packages/gunicorn/app/base.py", line 115, in wsgi
    self.callable = self.load()
  File "/usr/lib/python2.7/dist-packages/gunicorn/app/wsgiapp.py", line 33, in load
    return util.import_app(self.app_uri)
  File "/usr/lib/python2.7/dist-packages/gunicorn/util.py", line 362, in import_app
    __import__(module)
ImportError: No module named hello.py
2018-11-06 16:34:11 [448] [INFO] Worker exiting (pid: 448)
2018-11-06 16:34:11 [449] [INFO] Booting worker with pid: 449
2018-11-06 16:34:11 [449] [ERROR] Exception in worker process:
Traceback (most recent call last):
  File "/usr/lib/python2.7/dist-packages/gunicorn/arbiter.py", line 473, in spawn_worker
    worker.init_process()
  File "/usr/lib/python2.7/dist-packages/gunicorn/workers/base.py", line 100, in init_process
    self.wsgi = self.app.wsgi()
  File "/usr/lib/python2.7/dist-packages/gunicorn/app/base.py", line 115, in wsgi
    self.callable = self.load()
  File "/usr/lib/python2.7/dist-packages/gunicorn/app/wsgiapp.py", line 33, in load
    return util.import_app(self.app_uri)
  File "/usr/lib/python2.7/dist-packages/gunicorn/util.py", line 362, in import_app
    __import__(module)
ImportError: No module named hello.py
Traceback (most recent call last):
  File "/usr/lib/python2.7/dist-packages/gunicorn/arbiter.py", line 473, in spawn_worker
    worker.init_process()
  File "/usr/lib/python2.7/dist-packages/gunicorn/workers/base.py", line 100, in init_process
    self.wsgi = self.app.wsgi()
  File "/usr/lib/python2.7/dist-packages/gunicorn/app/base.py", line 115, in wsgi
    self.callable = self.load()
  File "/usr/lib/python2.7/dist-packages/gunicorn/app/wsgiapp.py", line 33, in load
    return util.import_app(self.app_uri)
  File "/usr/lib/python2.7/dist-packages/gunicorn/util.py", line 362, in import_app
    __import__(module)
ImportError: No module named hello.py
2018-11-06 16:34:11 [449] [INFO] Worker exiting (pid: 449)
2018-11-06 16:34:11 [450] [INFO] Booting worker with pid: 450
2018-11-06 16:34:11 [450] [ERROR] Exception in worker process:
Traceback (most recent call last):
  File "/usr/lib/python2.7/dist-packages/gunicorn/arbiter.py", line 473, in spawn_worker
    worker.init_process()
  File "/usr/lib/python2.7/dist-packages/gunicorn/workers/base.py", line 100, in init_process
    self.wsgi = self.app.wsgi()
  File "/usr/lib/python2.7/dist-packages/gunicorn/app/base.py", line 115, in wsgi
    self.callable = self.load()
  File "/usr/lib/python2.7/dist-packages/gunicorn/app/wsgiapp.py", line 33, in load
    return util.import_app(self.app_uri)
  File "/usr/lib/python2.7/dist-packages/gunicorn/util.py", line 362, in import_app
    __import__(module)
ImportError: No module named hello.py
Traceback (most recent call last):
  File "/usr/lib/python2.7/dist-packages/gunicorn/arbiter.py", line 473, in spawn_worker
    worker.init_process()
  File "/usr/lib/python2.7/dist-packages/gunicorn/workers/base.py", line 100, in init_process
    self.wsgi = self.app.wsgi()
  File "/usr/lib/python2.7/dist-packages/gunicorn/app/base.py", line 115, in wsgi
    self.callable = self.load()
  File "/usr/lib/python2.7/dist-packages/gunicorn/app/wsgiapp.py", line 33, in load
    return util.import_app(self.app_uri)
  File "/usr/lib/python2.7/dist-packages/gunicorn/util.py", line 362, in import_app
    __import__(module)
ImportError: No module named hello.py
2018-11-06 16:34:11 [450] [INFO] Worker exiting (pid: 450)
2018-11-06 16:34:11 [451] [INFO] Booting worker with pid: 451
2018-11-06 16:34:11 [451] [ERROR] Exception in worker process:
Traceback (most recent call last):
  File "/usr/lib/python2.7/dist-packages/gunicorn/arbiter.py", line 473, in spawn_worker
    worker.init_process()
  File "/usr/lib/python2.7/dist-packages/gunicorn/workers/base.py", line 100, in init_process
    self.wsgi = self.app.wsgi()
  File "/usr/lib/python2.7/dist-packages/gunicorn/app/base.py", line 115, in wsgi
    self.callable = self.load()
  File "/usr/lib/python2.7/dist-packages/gunicorn/app/wsgiapp.py", line 33, in load
    return util.import_app(self.app_uri)
  File "/usr/lib/python2.7/dist-packages/gunicorn/util.py", line 362, in import_app
    __import__(module)
ImportError: No module named hello.py
Traceback (most recent call last):
  File "/usr/lib/python2.7/dist-packages/gunicorn/arbiter.py", line 473, in spawn_worker
    worker.init_process()
  File "/usr/lib/python2.7/dist-packages/gunicorn/workers/base.py", line 100, in init_process
    self.wsgi = self.app.wsgi()
  File "/usr/lib/python2.7/dist-packages/gunicorn/app/base.py", line 115, in wsgi
    self.callable = self.load()
  File "/usr/lib/python2.7/dist-packages/gunicorn/app/wsgiapp.py", line 33, in load
    return util.import_app(self.app_uri)
  File "/usr/lib/python2.7/dist-packages/gunicorn/util.py", line 362, in import_app
    __import__(module)
ImportError: No module named hello.py
2018-11-06 16:34:11 [451] [INFO] Worker exiting (pid: 451)
Traceback (most recent call last):
  File "/usr/bin/gunicorn", line 9, in <module>
    load_entry_point('gunicorn==17.5', 'console_scripts', 'gunicorn')()
  File "/usr/lib/python2.7/dist-packages/gunicorn/app/wsgiapp.py", line 42, in run
    WSGIApplication("%(prog)s [OPTIONS] APP_MODULE").run()
  File "/usr/lib/python2.7/dist-packages/gunicorn/app/base.py", line 144, in run
    Arbiter(self).run()
  File "/usr/lib/python2.7/dist-packages/gunicorn/arbiter.py", line 196, in run
    self.halt(reason=inst.reason, exit_status=inst.exit_status)
  File "/usr/lib/python2.7/dist-packages/gunicorn/arbiter.py", line 291, in halt
    self.stop()
  File "/usr/lib/python2.7/dist-packages/gunicorn/arbiter.py", line 334, in stop
    self.reap_workers()
  File "/usr/lib/python2.7/dist-packages/gunicorn/arbiter.py", line 430, in reap_workers
    raise HaltServer(reason, self.WORKER_BOOT_ERROR)
gunicorn.errors.HaltServer: <HaltServer 'Worker failed to boot.' 3>
2018-11-06 16:39:53 [541] [INFO] Starting gunicorn 17.5
2018-11-06 16:39:53 [541] [INFO] Listening at: http://0.0.0.0:8000 (541)
2018-11-06 16:39:53 [541] [INFO] Using worker: sync
2018-11-06 16:39:53 [546] [INFO] Booting worker with pid: 546
2018-11-06 16:39:53 [546] [ERROR] Exception in worker process:
Traceback (most recent call last):
  File "/usr/lib/python2.7/dist-packages/gunicorn/arbiter.py", line 473, in spawn_worker
    worker.init_process()
  File "/usr/lib/python2.7/dist-packages/gunicorn/workers/base.py", line 100, in init_process
    self.wsgi = self.app.wsgi()
  File "/usr/lib/python2.7/dist-packages/gunicorn/app/base.py", line 115, in wsgi
    self.callable = self.load()
  File "/usr/lib/python2.7/dist-packages/gunicorn/app/wsgiapp.py", line 33, in load
    return util.import_app(self.app_uri)
  File "/usr/lib/python2.7/dist-packages/gunicorn/util.py", line 362, in import_app
    __import__(module)
ImportError: No module named hello.py
Traceback (most recent call last):
  File "/usr/lib/python2.7/dist-packages/gunicorn/arbiter.py", line 473, in spawn_worker
    worker.init_process()
  File "/usr/lib/python2.7/dist-packages/gunicorn/workers/base.py", line 100, in init_process
    self.wsgi = self.app.wsgi()
  File "/usr/lib/python2.7/dist-packages/gunicorn/app/base.py", line 115, in wsgi
    self.callable = self.load()
  File "/usr/lib/python2.7/dist-packages/gunicorn/app/wsgiapp.py", line 33, in load
    return util.import_app(self.app_uri)
  File "/usr/lib/python2.7/dist-packages/gunicorn/util.py", line 362, in import_app
    __import__(module)
ImportError: No module named hello.py
2018-11-06 16:39:53 [546] [INFO] Worker exiting (pid: 546)
2018-11-06 16:39:53 [547] [INFO] Booting worker with pid: 547
2018-11-06 16:39:53 [547] [ERROR] Exception in worker process:
Traceback (most recent call last):
  File "/usr/lib/python2.7/dist-packages/gunicorn/arbiter.py", line 473, in spawn_worker
    worker.init_process()
  File "/usr/lib/python2.7/dist-packages/gunicorn/workers/base.py", line 100, in init_process
    self.wsgi = self.app.wsgi()
  File "/usr/lib/python2.7/dist-packages/gunicorn/app/base.py", line 115, in wsgi
    self.callable = self.load()
  File "/usr/lib/python2.7/dist-packages/gunicorn/app/wsgiapp.py", line 33, in load
    return util.import_app(self.app_uri)
  File "/usr/lib/python2.7/dist-packages/gunicorn/util.py", line 362, in import_app
    __import__(module)
ImportError: No module named hello.py
Traceback (most recent call last):
  File "/usr/lib/python2.7/dist-packages/gunicorn/arbiter.py", line 473, in spawn_worker
    worker.init_process()
  File "/usr/lib/python2.7/dist-packages/gunicorn/workers/base.py", line 100, in init_process
    self.wsgi = self.app.wsgi()
  File "/usr/lib/python2.7/dist-packages/gunicorn/app/base.py", line 115, in wsgi
    self.callable = self.load()
  File "/usr/lib/python2.7/dist-packages/gunicorn/app/wsgiapp.py", line 33, in load
    return util.import_app(self.app_uri)
  File "/usr/lib/python2.7/dist-packages/gunicorn/util.py", line 362, in import_app
    __import__(module)
ImportError: No module named hello.py
2018-11-06 16:39:53 [547] [INFO] Worker exiting (pid: 547)
2018-11-06 16:39:53 [548] [INFO] Booting worker with pid: 548
2018-11-06 16:39:53 [548] [ERROR] Exception in worker process:
Traceback (most recent call last):
  File "/usr/lib/python2.7/dist-packages/gunicorn/arbiter.py", line 473, in spawn_worker
    worker.init_process()
  File "/usr/lib/python2.7/dist-packages/gunicorn/workers/base.py", line 100, in init_process
    self.wsgi = self.app.wsgi()
  File "/usr/lib/python2.7/dist-packages/gunicorn/app/base.py", line 115, in wsgi
    self.callable = self.load()
  File "/usr/lib/python2.7/dist-packages/gunicorn/app/wsgiapp.py", line 33, in load
    return util.import_app(self.app_uri)
  File "/usr/lib/python2.7/dist-packages/gunicorn/util.py", line 362, in import_app
    __import__(module)
ImportError: No module named hello.py
Traceback (most recent call last):
  File "/usr/lib/python2.7/dist-packages/gunicorn/arbiter.py", line 473, in spawn_worker
    worker.init_process()
  File "/usr/lib/python2.7/dist-packages/gunicorn/workers/base.py", line 100, in init_process
    self.wsgi = self.app.wsgi()
  File "/usr/lib/python2.7/dist-packages/gunicorn/app/base.py", line 115, in wsgi
    self.callable = self.load()
  File "/usr/lib/python2.7/dist-packages/gunicorn/app/wsgiapp.py", line 33, in load
    return util.import_app(self.app_uri)
  File "/usr/lib/python2.7/dist-packages/gunicorn/util.py", line 362, in import_app
    __import__(module)
ImportError: No module named hello.py
2018-11-06 16:39:53 [548] [INFO] Worker exiting (pid: 548)
2018-11-06 16:39:53 [549] [INFO] Booting worker with pid: 549
2018-11-06 16:39:53 [549] [ERROR] Exception in worker process:
Traceback (most recent call last):
  File "/usr/lib/python2.7/dist-packages/gunicorn/arbiter.py", line 473, in spawn_worker
    worker.init_process()
  File "/usr/lib/python2.7/dist-packages/gunicorn/workers/base.py", line 100, in init_process
    self.wsgi = self.app.wsgi()
  File "/usr/lib/python2.7/dist-packages/gunicorn/app/base.py", line 115, in wsgi
    self.callable = self.load()
  File "/usr/lib/python2.7/dist-packages/gunicorn/app/wsgiapp.py", line 33, in load
    return util.import_app(self.app_uri)
  File "/usr/lib/python2.7/dist-packages/gunicorn/util.py", line 362, in import_app
    __import__(module)
ImportError: No module named hello.py
Traceback (most recent call last):
  File "/usr/lib/python2.7/dist-packages/gunicorn/arbiter.py", line 473, in spawn_worker
    worker.init_process()
  File "/usr/lib/python2.7/dist-packages/gunicorn/workers/base.py", line 100, in init_process
    self.wsgi = self.app.wsgi()
  File "/usr/lib/python2.7/dist-packages/gunicorn/app/base.py", line 115, in wsgi
    self.callable = self.load()
  File "/usr/lib/python2.7/dist-packages/gunicorn/app/wsgiapp.py", line 33, in load
    return util.import_app(self.app_uri)
  File "/usr/lib/python2.7/dist-packages/gunicorn/util.py", line 362, in import_app
    __import__(module)
ImportError: No module named hello.py
2018-11-06 16:39:53 [549] [INFO] Worker exiting (pid: 549)
2018-11-06 16:39:53 [550] [INFO] Booting worker with pid: 550
2018-11-06 16:39:53 [550] [ERROR] Exception in worker process:
Traceback (most recent call last):
  File "/usr/lib/python2.7/dist-packages/gunicorn/arbiter.py", line 473, in spawn_worker
    worker.init_process()
  File "/usr/lib/python2.7/dist-packages/gunicorn/workers/base.py", line 100, in init_process
    self.wsgi = self.app.wsgi()
  File "/usr/lib/python2.7/dist-packages/gunicorn/app/base.py", line 115, in wsgi
    self.callable = self.load()
  File "/usr/lib/python2.7/dist-packages/gunicorn/app/wsgiapp.py", line 33, in load
    return util.import_app(self.app_uri)
  File "/usr/lib/python2.7/dist-packages/gunicorn/util.py", line 362, in import_app
    __import__(module)
ImportError: No module named hello.py
Traceback (most recent call last):
  File "/usr/lib/python2.7/dist-packages/gunicorn/arbiter.py", line 473, in spawn_worker
    worker.init_process()
  File "/usr/lib/python2.7/dist-packages/gunicorn/workers/base.py", line 100, in init_process
    self.wsgi = self.app.wsgi()
  File "/usr/lib/python2.7/dist-packages/gunicorn/app/base.py", line 115, in wsgi
    self.callable = self.load()
  File "/usr/lib/python2.7/dist-packages/gunicorn/app/wsgiapp.py", line 33, in load
    return util.import_app(self.app_uri)
  File "/usr/lib/python2.7/dist-packages/gunicorn/util.py", line 362, in import_app
    __import__(module)
ImportError: No module named hello.py
2018-11-06 16:39:53 [550] [INFO] Worker exiting (pid: 550)
2018-11-06 16:39:53 [551] [INFO] Booting worker with pid: 551
2018-11-06 16:39:53 [551] [ERROR] Exception in worker process:
Traceback (most recent call last):
  File "/usr/lib/python2.7/dist-packages/gunicorn/arbiter.py", line 473, in spawn_worker
    worker.init_process()
  File "/usr/lib/python2.7/dist-packages/gunicorn/workers/base.py", line 100, in init_process
    self.wsgi = self.app.wsgi()
  File "/usr/lib/python2.7/dist-packages/gunicorn/app/base.py", line 115, in wsgi
    self.callable = self.load()
  File "/usr/lib/python2.7/dist-packages/gunicorn/app/wsgiapp.py", line 33, in load
    return util.import_app(self.app_uri)
  File "/usr/lib/python2.7/dist-packages/gunicorn/util.py", line 362, in import_app
    __import__(module)
ImportError: No module named hello.py
Traceback (most recent call last):
  File "/usr/lib/python2.7/dist-packages/gunicorn/arbiter.py", line 473, in spawn_worker
    worker.init_process()
  File "/usr/lib/python2.7/dist-packages/gunicorn/workers/base.py", line 100, in init_process
    self.wsgi = self.app.wsgi()
  File "/usr/lib/python2.7/dist-packages/gunicorn/app/base.py", line 115, in wsgi
    self.callable = self.load()
  File "/usr/lib/python2.7/dist-packages/gunicorn/app/wsgiapp.py", line 33, in load
    return util.import_app(self.app_uri)
  File "/usr/lib/python2.7/dist-packages/gunicorn/util.py", line 362, in import_app
    __import__(module)
ImportError: No module named hello.py
2018-11-06 16:39:53 [551] [INFO] Worker exiting (pid: 551)
2018-11-06 16:39:53 [552] [INFO] Booting worker with pid: 552
2018-11-06 16:39:53 [552] [ERROR] Exception in worker process:
Traceback (most recent call last):
  File "/usr/lib/python2.7/dist-packages/gunicorn/arbiter.py", line 473, in spawn_worker
    worker.init_process()
  File "/usr/lib/python2.7/dist-packages/gunicorn/workers/base.py", line 100, in init_process
    self.wsgi = self.app.wsgi()
  File "/usr/lib/python2.7/dist-packages/gunicorn/app/base.py", line 115, in wsgi
    self.callable = self.load()
  File "/usr/lib/python2.7/dist-packages/gunicorn/app/wsgiapp.py", line 33, in load
    return util.import_app(self.app_uri)
  File "/usr/lib/python2.7/dist-packages/gunicorn/util.py", line 362, in import_app
    __import__(module)
ImportError: No module named hello.py
Traceback (most recent call last):
  File "/usr/lib/python2.7/dist-packages/gunicorn/arbiter.py", line 473, in spawn_worker
    worker.init_process()
  File "/usr/lib/python2.7/dist-packages/gunicorn/workers/base.py", line 100, in init_process
    self.wsgi = self.app.wsgi()
  File "/usr/lib/python2.7/dist-packages/gunicorn/app/base.py", line 115, in wsgi
    self.callable = self.load()
  File "/usr/lib/python2.7/dist-packages/gunicorn/app/wsgiapp.py", line 33, in load
    return util.import_app(self.app_uri)
  File "/usr/lib/python2.7/dist-packages/gunicorn/util.py", line 362, in import_app
    __import__(module)
ImportError: No module named hello.py
2018-11-06 16:39:53 [552] [INFO] Worker exiting (pid: 552)
2018-11-06 16:39:53 [553] [INFO] Booting worker with pid: 553
2018-11-06 16:39:53 [554] [INFO] Booting worker with pid: 554
2018-11-06 16:39:53 [554] [ERROR] Exception in worker process:
Traceback (most recent call last):
  File "/usr/lib/python2.7/dist-packages/gunicorn/arbiter.py", line 473, in spawn_worker
    worker.init_process()
  File "/usr/lib/python2.7/dist-packages/gunicorn/workers/base.py", line 100, in init_process
    self.wsgi = self.app.wsgi()
  File "/usr/lib/python2.7/dist-packages/gunicorn/app/base.py", line 115, in wsgi
    self.callable = self.load()
  File "/usr/lib/python2.7/dist-packages/gunicorn/app/wsgiapp.py", line 33, in load
    return util.import_app(self.app_uri)
  File "/usr/lib/python2.7/dist-packages/gunicorn/util.py", line 362, in import_app
    __import__(module)
ImportError: No module named hello.py
Traceback (most recent call last):
  File "/usr/lib/python2.7/dist-packages/gunicorn/arbiter.py", line 473, in spawn_worker
    worker.init_process()
  File "/usr/lib/python2.7/dist-packages/gunicorn/workers/base.py", line 100, in init_process
    self.wsgi = self.app.wsgi()
  File "/usr/lib/python2.7/dist-packages/gunicorn/app/base.py", line 115, in wsgi
    self.callable = self.load()
  File "/usr/lib/python2.7/dist-packages/gunicorn/app/wsgiapp.py", line 33, in load
    return util.import_app(self.app_uri)
  File "/usr/lib/python2.7/dist-packages/gunicorn/util.py", line 362, in import_app
    __import__(module)
ImportError: No module named hello.py
2018-11-06 16:39:53 [554] [INFO] Worker exiting (pid: 554)
2018-11-06 16:39:53 [553] [ERROR] Exception in worker process:
Traceback (most recent call last):
  File "/usr/lib/python2.7/dist-packages/gunicorn/arbiter.py", line 473, in spawn_worker
    worker.init_process()
  File "/usr/lib/python2.7/dist-packages/gunicorn/workers/base.py", line 100, in init_process
    self.wsgi = self.app.wsgi()
  File "/usr/lib/python2.7/dist-packages/gunicorn/app/base.py", line 115, in wsgi
    self.callable = self.load()
  File "/usr/lib/python2.7/dist-packages/gunicorn/app/wsgiapp.py", line 33, in load
    return util.import_app(self.app_uri)
  File "/usr/lib/python2.7/dist-packages/gunicorn/util.py", line 362, in import_app
    __import__(module)
ImportError: No module named hello.py
Traceback (most recent call last):
  File "/usr/lib/python2.7/dist-packages/gunicorn/arbiter.py", line 473, in spawn_worker
    worker.init_process()
  File "/usr/lib/python2.7/dist-packages/gunicorn/workers/base.py", line 100, in init_process
    self.wsgi = self.app.wsgi()
  File "/usr/lib/python2.7/dist-packages/gunicorn/app/base.py", line 115, in wsgi
    self.callable = self.load()
  File "/usr/lib/python2.7/dist-packages/gunicorn/app/wsgiapp.py", line 33, in load
    return util.import_app(self.app_uri)
  File "/usr/lib/python2.7/dist-packages/gunicorn/util.py", line 362, in import_app
    __import__(module)
ImportError: No module named hello.py
2018-11-06 16:39:53 [553] [INFO] Worker exiting (pid: 553)
2018-11-06 16:39:53 [555] [INFO] Booting worker with pid: 555
2018-11-06 16:39:53 [555] [ERROR] Exception in worker process:
Traceback (most recent call last):
  File "/usr/lib/python2.7/dist-packages/gunicorn/arbiter.py", line 473, in spawn_worker
    worker.init_process()
  File "/usr/lib/python2.7/dist-packages/gunicorn/workers/base.py", line 100, in init_process
    self.wsgi = self.app.wsgi()
  File "/usr/lib/python2.7/dist-packages/gunicorn/app/base.py", line 115, in wsgi
    self.callable = self.load()
  File "/usr/lib/python2.7/dist-packages/gunicorn/app/wsgiapp.py", line 33, in load
    return util.import_app(self.app_uri)
  File "/usr/lib/python2.7/dist-packages/gunicorn/util.py", line 362, in import_app
    __import__(module)
ImportError: No module named hello.py
Traceback (most recent call last):
  File "/usr/lib/python2.7/dist-packages/gunicorn/arbiter.py", line 473, in spawn_worker
    worker.init_process()
  File "/usr/lib/python2.7/dist-packages/gunicorn/workers/base.py", line 100, in init_process
    self.wsgi = self.app.wsgi()
  File "/usr/lib/python2.7/dist-packages/gunicorn/app/base.py", line 115, in wsgi
    self.callable = self.load()
  File "/usr/lib/python2.7/dist-packages/gunicorn/app/wsgiapp.py", line 33, in load
    return util.import_app(self.app_uri)
  File "/usr/lib/python2.7/dist-packages/gunicorn/util.py", line 362, in import_app
    __import__(module)
ImportError: No module named hello.py
2018-11-06 16:39:53 [555] [INFO] Worker exiting (pid: 555)
2018-11-06 16:39:53 [556] [INFO] Booting worker with pid: 556
2018-11-06 16:39:53 [556] [ERROR] Exception in worker process:
Traceback (most recent call last):
  File "/usr/lib/python2.7/dist-packages/gunicorn/arbiter.py", line 473, in spawn_worker
    worker.init_process()
  File "/usr/lib/python2.7/dist-packages/gunicorn/workers/base.py", line 100, in init_process
    self.wsgi = self.app.wsgi()
  File "/usr/lib/python2.7/dist-packages/gunicorn/app/base.py", line 115, in wsgi
    self.callable = self.load()
  File "/usr/lib/python2.7/dist-packages/gunicorn/app/wsgiapp.py", line 33, in load
    return util.import_app(self.app_uri)
  File "/usr/lib/python2.7/dist-packages/gunicorn/util.py", line 362, in import_app
    __import__(module)
ImportError: No module named hello.py
Traceback (most recent call last):
  File "/usr/lib/python2.7/dist-packages/gunicorn/arbiter.py", line 473, in spawn_worker
    worker.init_process()
  File "/usr/lib/python2.7/dist-packages/gunicorn/workers/base.py", line 100, in init_process
    self.wsgi = self.app.wsgi()
  File "/usr/lib/python2.7/dist-packages/gunicorn/app/base.py", line 115, in wsgi
    self.callable = self.load()
  File "/usr/lib/python2.7/dist-packages/gunicorn/app/wsgiapp.py", line 33, in load
    return util.import_app(self.app_uri)
  File "/usr/lib/python2.7/dist-packages/gunicorn/util.py", line 362, in import_app
    __import__(module)
ImportError: No module named hello.py
2018-11-06 16:39:53 [556] [INFO] Worker exiting (pid: 556)
2018-11-06 16:39:53 [557] [INFO] Booting worker with pid: 557
2018-11-06 16:39:53 [557] [ERROR] Exception in worker process:
Traceback (most recent call last):
  File "/usr/lib/python2.7/dist-packages/gunicorn/arbiter.py", line 473, in spawn_worker
    worker.init_process()
  File "/usr/lib/python2.7/dist-packages/gunicorn/workers/base.py", line 100, in init_process
    self.wsgi = self.app.wsgi()
  File "/usr/lib/python2.7/dist-packages/gunicorn/app/base.py", line 115, in wsgi
    self.callable = self.load()
  File "/usr/lib/python2.7/dist-packages/gunicorn/app/wsgiapp.py", line 33, in load
    return util.import_app(self.app_uri)
  File "/usr/lib/python2.7/dist-packages/gunicorn/util.py", line 362, in import_app
    __import__(module)
ImportError: No module named hello.py
Traceback (most recent call last):
  File "/usr/lib/python2.7/dist-packages/gunicorn/arbiter.py", line 473, in spawn_worker
    worker.init_process()
  File "/usr/lib/python2.7/dist-packages/gunicorn/workers/base.py", line 100, in init_process
    self.wsgi = self.app.wsgi()
  File "/usr/lib/python2.7/dist-packages/gunicorn/app/base.py", line 115, in wsgi
    self.callable = self.load()
  File "/usr/lib/python2.7/dist-packages/gunicorn/app/wsgiapp.py", line 33, in load
    return util.import_app(self.app_uri)
  File "/usr/lib/python2.7/dist-packages/gunicorn/util.py", line 362, in import_app
    __import__(module)
ImportError: No module named hello.py
2018-11-06 16:39:53 [557] [INFO] Worker exiting (pid: 557)
2018-11-06 16:39:53 [558] [INFO] Booting worker with pid: 558
2018-11-06 16:39:53 [558] [ERROR] Exception in worker process:
Traceback (most recent call last):
  File "/usr/lib/python2.7/dist-packages/gunicorn/arbiter.py", line 473, in spawn_worker
    worker.init_process()
  File "/usr/lib/python2.7/dist-packages/gunicorn/workers/base.py", line 100, in init_process
    self.wsgi = self.app.wsgi()
  File "/usr/lib/python2.7/dist-packages/gunicorn/app/base.py", line 115, in wsgi
    self.callable = self.load()
  File "/usr/lib/python2.7/dist-packages/gunicorn/app/wsgiapp.py", line 33, in load
    return util.import_app(self.app_uri)
  File "/usr/lib/python2.7/dist-packages/gunicorn/util.py", line 362, in import_app
    __import__(module)
ImportError: No module named hello.py
Traceback (most recent call last):
  File "/usr/lib/python2.7/dist-packages/gunicorn/arbiter.py", line 473, in spawn_worker
    worker.init_process()
  File "/usr/lib/python2.7/dist-packages/gunicorn/workers/base.py", line 100, in init_process
    self.wsgi = self.app.wsgi()
  File "/usr/lib/python2.7/dist-packages/gunicorn/app/base.py", line 115, in wsgi
    self.callable = self.load()
  File "/usr/lib/python2.7/dist-packages/gunicorn/app/wsgiapp.py", line 33, in load
    return util.import_app(self.app_uri)
  File "/usr/lib/python2.7/dist-packages/gunicorn/util.py", line 362, in import_app
    __import__(module)
ImportError: No module named hello.py
2018-11-06 16:39:53 [558] [INFO] Worker exiting (pid: 558)
2018-11-06 16:39:53 [559] [INFO] Booting worker with pid: 559
2018-11-06 16:39:53 [559] [ERROR] Exception in worker process:
Traceback (most recent call last):
  File "/usr/lib/python2.7/dist-packages/gunicorn/arbiter.py", line 473, in spawn_worker
    worker.init_process()
  File "/usr/lib/python2.7/dist-packages/gunicorn/workers/base.py", line 100, in init_process
    self.wsgi = self.app.wsgi()
  File "/usr/lib/python2.7/dist-packages/gunicorn/app/base.py", line 115, in wsgi
    self.callable = self.load()
  File "/usr/lib/python2.7/dist-packages/gunicorn/app/wsgiapp.py", line 33, in load
    return util.import_app(self.app_uri)
  File "/usr/lib/python2.7/dist-packages/gunicorn/util.py", line 362, in import_app
    __import__(module)
ImportError: No module named hello.py
Traceback (most recent call last):
  File "/usr/lib/python2.7/dist-packages/gunicorn/arbiter.py", line 473, in spawn_worker
    worker.init_process()
  File "/usr/lib/python2.7/dist-packages/gunicorn/workers/base.py", line 100, in init_process
    self.wsgi = self.app.wsgi()
  File "/usr/lib/python2.7/dist-packages/gunicorn/app/base.py", line 115, in wsgi
    self.callable = self.load()
  File "/usr/lib/python2.7/dist-packages/gunicorn/app/wsgiapp.py", line 33, in load
    return util.import_app(self.app_uri)
  File "/usr/lib/python2.7/dist-packages/gunicorn/util.py", line 362, in import_app
    __import__(module)
ImportError: No module named hello.py
2018-11-06 16:39:53 [559] [INFO] Worker exiting (pid: 559)
2018-11-06 16:39:53 [560] [INFO] Booting worker with pid: 560
2018-11-06 16:39:53 [560] [ERROR] Exception in worker process:
Traceback (most recent call last):
  File "/usr/lib/python2.7/dist-packages/gunicorn/arbiter.py", line 473, in spawn_worker
    worker.init_process()
  File "/usr/lib/python2.7/dist-packages/gunicorn/workers/base.py", line 100, in init_process
    self.wsgi = self.app.wsgi()
  File "/usr/lib/python2.7/dist-packages/gunicorn/app/base.py", line 115, in wsgi
    self.callable = self.load()
  File "/usr/lib/python2.7/dist-packages/gunicorn/app/wsgiapp.py", line 33, in load
    return util.import_app(self.app_uri)
  File "/usr/lib/python2.7/dist-packages/gunicorn/util.py", line 362, in import_app
    __import__(module)
ImportError: No module named hello.py
Traceback (most recent call last):
  File "/usr/lib/python2.7/dist-packages/gunicorn/arbiter.py", line 473, in spawn_worker
    worker.init_process()
  File "/usr/lib/python2.7/dist-packages/gunicorn/workers/base.py", line 100, in init_process
    self.wsgi = self.app.wsgi()
  File "/usr/lib/python2.7/dist-packages/gunicorn/app/base.py", line 115, in wsgi
    self.callable = self.load()
  File "/usr/lib/python2.7/dist-packages/gunicorn/app/wsgiapp.py", line 33, in load
    return util.import_app(self.app_uri)
  File "/usr/lib/python2.7/dist-packages/gunicorn/util.py", line 362, in import_app
    __import__(module)
ImportError: No module named hello.py
2018-11-06 16:39:53 [560] [INFO] Worker exiting (pid: 560)
2018-11-06 16:39:53 [561] [INFO] Booting worker with pid: 561
2018-11-06 16:39:53 [561] [ERROR] Exception in worker process:
Traceback (most recent call last):
  File "/usr/lib/python2.7/dist-packages/gunicorn/arbiter.py", line 473, in spawn_worker
    worker.init_process()
  File "/usr/lib/python2.7/dist-packages/gunicorn/workers/base.py", line 100, in init_process
    self.wsgi = self.app.wsgi()
  File "/usr/lib/python2.7/dist-packages/gunicorn/app/base.py", line 115, in wsgi
    self.callable = self.load()
  File "/usr/lib/python2.7/dist-packages/gunicorn/app/wsgiapp.py", line 33, in load
    return util.import_app(self.app_uri)
  File "/usr/lib/python2.7/dist-packages/gunicorn/util.py", line 362, in import_app
    __import__(module)
ImportError: No module named hello.py
Traceback (most recent call last):
  File "/usr/lib/python2.7/dist-packages/gunicorn/arbiter.py", line 473, in spawn_worker
    worker.init_process()
  File "/usr/lib/python2.7/dist-packages/gunicorn/workers/base.py", line 100, in init_process
    self.wsgi = self.app.wsgi()
  File "/usr/lib/python2.7/dist-packages/gunicorn/app/base.py", line 115, in wsgi
    self.callable = self.load()
  File "/usr/lib/python2.7/dist-packages/gunicorn/app/wsgiapp.py", line 33, in load
    return util.import_app(self.app_uri)
  File "/usr/lib/python2.7/dist-packages/gunicorn/util.py", line 362, in import_app
    __import__(module)
ImportError: No module named hello.py
2018-11-06 16:39:53 [561] [INFO] Worker exiting (pid: 561)
Traceback (most recent call last):
  File "/usr/bin/gunicorn", line 9, in <module>
    load_entry_point('gunicorn==17.5', 'console_scripts', 'gunicorn')()
  File "/usr/lib/python2.7/dist-packages/gunicorn/app/wsgiapp.py", line 42, in run
    WSGIApplication("%(prog)s [OPTIONS] APP_MODULE").run()
  File "/usr/lib/python2.7/dist-packages/gunicorn/app/base.py", line 144, in run
    Arbiter(self).run()
  File "/usr/lib/python2.7/dist-packages/gunicorn/arbiter.py", line 196, in run
    self.halt(reason=inst.reason, exit_status=inst.exit_status)
  File "/usr/lib/python2.7/dist-packages/gunicorn/arbiter.py", line 291, in halt
    self.stop()
  File "/usr/lib/python2.7/dist-packages/gunicorn/arbiter.py", line 334, in stop
    self.reap_workers()
  File "/usr/lib/python2.7/dist-packages/gunicorn/arbiter.py", line 430, in reap_workers
    raise HaltServer(reason, self.WORKER_BOOT_ERROR)
gunicorn.errors.HaltServer: <HaltServer 'Worker failed to boot.' 3>
2018-11-06 16:42:56 [645] [INFO] Starting gunicorn 17.5
2018-11-06 16:42:56 [645] [INFO] Listening at: http://0.0.0.0:8000 (645)
2018-11-06 16:42:56 [645] [INFO] Using worker: sync
2018-11-06 16:42:56 [650] [INFO] Booting worker with pid: 650
2018-11-06 16:42:56 [650] [ERROR] Exception in worker process:
Traceback (most recent call last):
  File "/usr/lib/python2.7/dist-packages/gunicorn/arbiter.py", line 473, in spawn_worker
    worker.init_process()
  File "/usr/lib/python2.7/dist-packages/gunicorn/workers/base.py", line 100, in init_process
    self.wsgi = self.app.wsgi()
  File "/usr/lib/python2.7/dist-packages/gunicorn/app/base.py", line 115, in wsgi
    self.callable = self.load()
  File "/usr/lib/python2.7/dist-packages/gunicorn/app/wsgiapp.py", line 33, in load
    return util.import_app(self.app_uri)
  File "/usr/lib/python2.7/dist-packages/gunicorn/util.py", line 362, in import_app
    __import__(module)
ImportError: No module named hello.py
Traceback (most recent call last):
  File "/usr/lib/python2.7/dist-packages/gunicorn/arbiter.py", line 473, in spawn_worker
    worker.init_process()
  File "/usr/lib/python2.7/dist-packages/gunicorn/workers/base.py", line 100, in init_process
    self.wsgi = self.app.wsgi()
  File "/usr/lib/python2.7/dist-packages/gunicorn/app/base.py", line 115, in wsgi
    self.callable = self.load()
  File "/usr/lib/python2.7/dist-packages/gunicorn/app/wsgiapp.py", line 33, in load
    return util.import_app(self.app_uri)
  File "/usr/lib/python2.7/dist-packages/gunicorn/util.py", line 362, in import_app
    __import__(module)
ImportError: No module named hello.py
2018-11-06 16:42:56 [650] [INFO] Worker exiting (pid: 650)
2018-11-06 16:42:56 [651] [INFO] Booting worker with pid: 651
2018-11-06 16:42:56 [651] [ERROR] Exception in worker process:
Traceback (most recent call last):
  File "/usr/lib/python2.7/dist-packages/gunicorn/arbiter.py", line 473, in spawn_worker
    worker.init_process()
  File "/usr/lib/python2.7/dist-packages/gunicorn/workers/base.py", line 100, in init_process
    self.wsgi = self.app.wsgi()
  File "/usr/lib/python2.7/dist-packages/gunicorn/app/base.py", line 115, in wsgi
    self.callable = self.load()
  File "/usr/lib/python2.7/dist-packages/gunicorn/app/wsgiapp.py", line 33, in load
    return util.import_app(self.app_uri)
  File "/usr/lib/python2.7/dist-packages/gunicorn/util.py", line 362, in import_app
    __import__(module)
ImportError: No module named hello.py
Traceback (most recent call last):
  File "/usr/lib/python2.7/dist-packages/gunicorn/arbiter.py", line 473, in spawn_worker
    worker.init_process()
  File "/usr/lib/python2.7/dist-packages/gunicorn/workers/base.py", line 100, in init_process
    self.wsgi = self.app.wsgi()
  File "/usr/lib/python2.7/dist-packages/gunicorn/app/base.py", line 115, in wsgi
    self.callable = self.load()
  File "/usr/lib/python2.7/dist-packages/gunicorn/app/wsgiapp.py", line 33, in load
    return util.import_app(self.app_uri)
  File "/usr/lib/python2.7/dist-packages/gunicorn/util.py", line 362, in import_app
    __import__(module)
ImportError: No module named hello.py
2018-11-06 16:42:56 [651] [INFO] Worker exiting (pid: 651)
2018-11-06 16:42:56 [652] [INFO] Booting worker with pid: 652
2018-11-06 16:42:56 [652] [ERROR] Exception in worker process:
Traceback (most recent call last):
  File "/usr/lib/python2.7/dist-packages/gunicorn/arbiter.py", line 473, in spawn_worker
    worker.init_process()
  File "/usr/lib/python2.7/dist-packages/gunicorn/workers/base.py", line 100, in init_process
    self.wsgi = self.app.wsgi()
  File "/usr/lib/python2.7/dist-packages/gunicorn/app/base.py", line 115, in wsgi
    self.callable = self.load()
  File "/usr/lib/python2.7/dist-packages/gunicorn/app/wsgiapp.py", line 33, in load
    return util.import_app(self.app_uri)
  File "/usr/lib/python2.7/dist-packages/gunicorn/util.py", line 362, in import_app
    __import__(module)
ImportError: No module named hello.py
Traceback (most recent call last):
  File "/usr/lib/python2.7/dist-packages/gunicorn/arbiter.py", line 473, in spawn_worker
    worker.init_process()
  File "/usr/lib/python2.7/dist-packages/gunicorn/workers/base.py", line 100, in init_process
    self.wsgi = self.app.wsgi()
  File "/usr/lib/python2.7/dist-packages/gunicorn/app/base.py", line 115, in wsgi
    self.callable = self.load()
  File "/usr/lib/python2.7/dist-packages/gunicorn/app/wsgiapp.py", line 33, in load
    return util.import_app(self.app_uri)
  File "/usr/lib/python2.7/dist-packages/gunicorn/util.py", line 362, in import_app
    __import__(module)
ImportError: No module named hello.py
2018-11-06 16:42:56 [652] [INFO] Worker exiting (pid: 652)
2018-11-06 16:42:56 [653] [INFO] Booting worker with pid: 653
2018-11-06 16:42:56 [653] [ERROR] Exception in worker process:
Traceback (most recent call last):
  File "/usr/lib/python2.7/dist-packages/gunicorn/arbiter.py", line 473, in spawn_worker
    worker.init_process()
  File "/usr/lib/python2.7/dist-packages/gunicorn/workers/base.py", line 100, in init_process
    self.wsgi = self.app.wsgi()
  File "/usr/lib/python2.7/dist-packages/gunicorn/app/base.py", line 115, in wsgi
    self.callable = self.load()
  File "/usr/lib/python2.7/dist-packages/gunicorn/app/wsgiapp.py", line 33, in load
    return util.import_app(self.app_uri)
  File "/usr/lib/python2.7/dist-packages/gunicorn/util.py", line 362, in import_app
    __import__(module)
ImportError: No module named hello.py
Traceback (most recent call last):
  File "/usr/lib/python2.7/dist-packages/gunicorn/arbiter.py", line 473, in spawn_worker
    worker.init_process()
  File "/usr/lib/python2.7/dist-packages/gunicorn/workers/base.py", line 100, in init_process
    self.wsgi = self.app.wsgi()
  File "/usr/lib/python2.7/dist-packages/gunicorn/app/base.py", line 115, in wsgi
    self.callable = self.load()
  File "/usr/lib/python2.7/dist-packages/gunicorn/app/wsgiapp.py", line 33, in load
    return util.import_app(self.app_uri)
  File "/usr/lib/python2.7/dist-packages/gunicorn/util.py", line 362, in import_app
    __import__(module)
ImportError: No module named hello.py
2018-11-06 16:42:56 [653] [INFO] Worker exiting (pid: 653)
2018-11-06 16:42:56 [654] [INFO] Booting worker with pid: 654
2018-11-06 16:42:56 [654] [ERROR] Exception in worker process:
Traceback (most recent call last):
  File "/usr/lib/python2.7/dist-packages/gunicorn/arbiter.py", line 473, in spawn_worker
    worker.init_process()
  File "/usr/lib/python2.7/dist-packages/gunicorn/workers/base.py", line 100, in init_process
    self.wsgi = self.app.wsgi()
  File "/usr/lib/python2.7/dist-packages/gunicorn/app/base.py", line 115, in wsgi
    self.callable = self.load()
  File "/usr/lib/python2.7/dist-packages/gunicorn/app/wsgiapp.py", line 33, in load
    return util.import_app(self.app_uri)
  File "/usr/lib/python2.7/dist-packages/gunicorn/util.py", line 362, in import_app
    __import__(module)
ImportError: No module named hello.py
Traceback (most recent call last):
  File "/usr/lib/python2.7/dist-packages/gunicorn/arbiter.py", line 473, in spawn_worker
    worker.init_process()
  File "/usr/lib/python2.7/dist-packages/gunicorn/workers/base.py", line 100, in init_process
    self.wsgi = self.app.wsgi()
  File "/usr/lib/python2.7/dist-packages/gunicorn/app/base.py", line 115, in wsgi
    self.callable = self.load()
  File "/usr/lib/python2.7/dist-packages/gunicorn/app/wsgiapp.py", line 33, in load
    return util.import_app(self.app_uri)
  File "/usr/lib/python2.7/dist-packages/gunicorn/util.py", line 362, in import_app
    __import__(module)
ImportError: No module named hello.py
2018-11-06 16:42:56 [654] [INFO] Worker exiting (pid: 654)
2018-11-06 16:42:56 [655] [INFO] Booting worker with pid: 655
2018-11-06 16:42:56 [655] [ERROR] Exception in worker process:
Traceback (most recent call last):
  File "/usr/lib/python2.7/dist-packages/gunicorn/arbiter.py", line 473, in spawn_worker
    worker.init_process()
  File "/usr/lib/python2.7/dist-packages/gunicorn/workers/base.py", line 100, in init_process
    self.wsgi = self.app.wsgi()
  File "/usr/lib/python2.7/dist-packages/gunicorn/app/base.py", line 115, in wsgi
    self.callable = self.load()
  File "/usr/lib/python2.7/dist-packages/gunicorn/app/wsgiapp.py", line 33, in load
    return util.import_app(self.app_uri)
  File "/usr/lib/python2.7/dist-packages/gunicorn/util.py", line 362, in import_app
    __import__(module)
ImportError: No module named hello.py
Traceback (most recent call last):
  File "/usr/lib/python2.7/dist-packages/gunicorn/arbiter.py", line 473, in spawn_worker
    worker.init_process()
  File "/usr/lib/python2.7/dist-packages/gunicorn/workers/base.py", line 100, in init_process
    self.wsgi = self.app.wsgi()
  File "/usr/lib/python2.7/dist-packages/gunicorn/app/base.py", line 115, in wsgi
    self.callable = self.load()
  File "/usr/lib/python2.7/dist-packages/gunicorn/app/wsgiapp.py", line 33, in load
    return util.import_app(self.app_uri)
  File "/usr/lib/python2.7/dist-packages/gunicorn/util.py", line 362, in import_app
    __import__(module)
ImportError: No module named hello.py
2018-11-06 16:42:56 [655] [INFO] Worker exiting (pid: 655)
2018-11-06 16:42:56 [656] [INFO] Booting worker with pid: 656
2018-11-06 16:42:56 [656] [ERROR] Exception in worker process:
Traceback (most recent call last):
  File "/usr/lib/python2.7/dist-packages/gunicorn/arbiter.py", line 473, in spawn_worker
    worker.init_process()
  File "/usr/lib/python2.7/dist-packages/gunicorn/workers/base.py", line 100, in init_process
    self.wsgi = self.app.wsgi()
  File "/usr/lib/python2.7/dist-packages/gunicorn/app/base.py", line 115, in wsgi
    self.callable = self.load()
  File "/usr/lib/python2.7/dist-packages/gunicorn/app/wsgiapp.py", line 33, in load
    return util.import_app(self.app_uri)
  File "/usr/lib/python2.7/dist-packages/gunicorn/util.py", line 362, in import_app
    __import__(module)
ImportError: No module named hello.py
Traceback (most recent call last):
  File "/usr/lib/python2.7/dist-packages/gunicorn/arbiter.py", line 473, in spawn_worker
    worker.init_process()
  File "/usr/lib/python2.7/dist-packages/gunicorn/workers/base.py", line 100, in init_process
    self.wsgi = self.app.wsgi()
  File "/usr/lib/python2.7/dist-packages/gunicorn/app/base.py", line 115, in wsgi
    self.callable = self.load()
  File "/usr/lib/python2.7/dist-packages/gunicorn/app/wsgiapp.py", line 33, in load
    return util.import_app(self.app_uri)
  File "/usr/lib/python2.7/dist-packages/gunicorn/util.py", line 362, in import_app
    __import__(module)
ImportError: No module named hello.py
2018-11-06 16:42:56 [656] [INFO] Worker exiting (pid: 656)
2018-11-06 16:42:56 [657] [INFO] Booting worker with pid: 657
2018-11-06 16:42:56 [657] [ERROR] Exception in worker process:
Traceback (most recent call last):
  File "/usr/lib/python2.7/dist-packages/gunicorn/arbiter.py", line 473, in spawn_worker
    worker.init_process()
  File "/usr/lib/python2.7/dist-packages/gunicorn/workers/base.py", line 100, in init_process
    self.wsgi = self.app.wsgi()
  File "/usr/lib/python2.7/dist-packages/gunicorn/app/base.py", line 115, in wsgi
    self.callable = self.load()
  File "/usr/lib/python2.7/dist-packages/gunicorn/app/wsgiapp.py", line 33, in load
    return util.import_app(self.app_uri)
  File "/usr/lib/python2.7/dist-packages/gunicorn/util.py", line 362, in import_app
    __import__(module)
ImportError: No module named hello.py
Traceback (most recent call last):
  File "/usr/lib/python2.7/dist-packages/gunicorn/arbiter.py", line 473, in spawn_worker
    worker.init_process()
  File "/usr/lib/python2.7/dist-packages/gunicorn/workers/base.py", line 100, in init_process
    self.wsgi = self.app.wsgi()
  File "/usr/lib/python2.7/dist-packages/gunicorn/app/base.py", line 115, in wsgi
    self.callable = self.load()
  File "/usr/lib/python2.7/dist-packages/gunicorn/app/wsgiapp.py", line 33, in load
    return util.import_app(self.app_uri)
  File "/usr/lib/python2.7/dist-packages/gunicorn/util.py", line 362, in import_app
    __import__(module)
ImportError: No module named hello.py
2018-11-06 16:42:56 [657] [INFO] Worker exiting (pid: 657)
2018-11-06 16:42:56 [658] [INFO] Booting worker with pid: 658
2018-11-06 16:42:56 [658] [ERROR] Exception in worker process:
Traceback (most recent call last):
  File "/usr/lib/python2.7/dist-packages/gunicorn/arbiter.py", line 473, in spawn_worker
    worker.init_process()
  File "/usr/lib/python2.7/dist-packages/gunicorn/workers/base.py", line 100, in init_process
    self.wsgi = self.app.wsgi()
  File "/usr/lib/python2.7/dist-packages/gunicorn/app/base.py", line 115, in wsgi
    self.callable = self.load()
  File "/usr/lib/python2.7/dist-packages/gunicorn/app/wsgiapp.py", line 33, in load
    return util.import_app(self.app_uri)
  File "/usr/lib/python2.7/dist-packages/gunicorn/util.py", line 362, in import_app
    __import__(module)
ImportError: No module named hello.py
Traceback (most recent call last):
  File "/usr/lib/python2.7/dist-packages/gunicorn/arbiter.py", line 473, in spawn_worker
    worker.init_process()
  File "/usr/lib/python2.7/dist-packages/gunicorn/workers/base.py", line 100, in init_process
    self.wsgi = self.app.wsgi()
  File "/usr/lib/python2.7/dist-packages/gunicorn/app/base.py", line 115, in wsgi
    self.callable = self.load()
  File "/usr/lib/python2.7/dist-packages/gunicorn/app/wsgiapp.py", line 33, in load
    return util.import_app(self.app_uri)
  File "/usr/lib/python2.7/dist-packages/gunicorn/util.py", line 362, in import_app
    __import__(module)
ImportError: No module named hello.py
2018-11-06 16:42:56 [658] [INFO] Worker exiting (pid: 658)
2018-11-06 16:42:56 [659] [INFO] Booting worker with pid: 659
2018-11-06 16:42:56 [659] [ERROR] Exception in worker process:
Traceback (most recent call last):
  File "/usr/lib/python2.7/dist-packages/gunicorn/arbiter.py", line 473, in spawn_worker
    worker.init_process()
  File "/usr/lib/python2.7/dist-packages/gunicorn/workers/base.py", line 100, in init_process
    self.wsgi = self.app.wsgi()
  File "/usr/lib/python2.7/dist-packages/gunicorn/app/base.py", line 115, in wsgi
    self.callable = self.load()
  File "/usr/lib/python2.7/dist-packages/gunicorn/app/wsgiapp.py", line 33, in load
    return util.import_app(self.app_uri)
  File "/usr/lib/python2.7/dist-packages/gunicorn/util.py", line 362, in import_app
    __import__(module)
ImportError: No module named hello.py
Traceback (most recent call last):
  File "/usr/lib/python2.7/dist-packages/gunicorn/arbiter.py", line 473, in spawn_worker
    worker.init_process()
  File "/usr/lib/python2.7/dist-packages/gunicorn/workers/base.py", line 100, in init_process
    self.wsgi = self.app.wsgi()
  File "/usr/lib/python2.7/dist-packages/gunicorn/app/base.py", line 115, in wsgi
    self.callable = self.load()
  File "/usr/lib/python2.7/dist-packages/gunicorn/app/wsgiapp.py", line 33, in load
    return util.import_app(self.app_uri)
  File "/usr/lib/python2.7/dist-packages/gunicorn/util.py", line 362, in import_app
    __import__(module)
ImportError: No module named hello.py
2018-11-06 16:42:56 [659] [INFO] Worker exiting (pid: 659)
2018-11-06 16:42:56 [660] [INFO] Booting worker with pid: 660
2018-11-06 16:42:56 [660] [ERROR] Exception in worker process:
Traceback (most recent call last):
  File "/usr/lib/python2.7/dist-packages/gunicorn/arbiter.py", line 473, in spawn_worker
    worker.init_process()
  File "/usr/lib/python2.7/dist-packages/gunicorn/workers/base.py", line 100, in init_process
    self.wsgi = self.app.wsgi()
  File "/usr/lib/python2.7/dist-packages/gunicorn/app/base.py", line 115, in wsgi
    self.callable = self.load()
  File "/usr/lib/python2.7/dist-packages/gunicorn/app/wsgiapp.py", line 33, in load
    return util.import_app(self.app_uri)
  File "/usr/lib/python2.7/dist-packages/gunicorn/util.py", line 362, in import_app
    __import__(module)
ImportError: No module named hello.py
Traceback (most recent call last):
  File "/usr/lib/python2.7/dist-packages/gunicorn/arbiter.py", line 473, in spawn_worker
    worker.init_process()
  File "/usr/lib/python2.7/dist-packages/gunicorn/workers/base.py", line 100, in init_process
    self.wsgi = self.app.wsgi()
  File "/usr/lib/python2.7/dist-packages/gunicorn/app/base.py", line 115, in wsgi
    self.callable = self.load()
  File "/usr/lib/python2.7/dist-packages/gunicorn/app/wsgiapp.py", line 33, in load
    return util.import_app(self.app_uri)
  File "/usr/lib/python2.7/dist-packages/gunicorn/util.py", line 362, in import_app
    __import__(module)
ImportError: No module named hello.py
2018-11-06 16:42:56 [660] [INFO] Worker exiting (pid: 660)
2018-11-06 16:42:56 [661] [INFO] Booting worker with pid: 661
2018-11-06 16:42:56 [661] [ERROR] Exception in worker process:
Traceback (most recent call last):
  File "/usr/lib/python2.7/dist-packages/gunicorn/arbiter.py", line 473, in spawn_worker
    worker.init_process()
  File "/usr/lib/python2.7/dist-packages/gunicorn/workers/base.py", line 100, in init_process
    self.wsgi = self.app.wsgi()
  File "/usr/lib/python2.7/dist-packages/gunicorn/app/base.py", line 115, in wsgi
    self.callable = self.load()
  File "/usr/lib/python2.7/dist-packages/gunicorn/app/wsgiapp.py", line 33, in load
    return util.import_app(self.app_uri)
  File "/usr/lib/python2.7/dist-packages/gunicorn/util.py", line 362, in import_app
    __import__(module)
ImportError: No module named hello.py
Traceback (most recent call last):
  File "/usr/lib/python2.7/dist-packages/gunicorn/arbiter.py", line 473, in spawn_worker
    worker.init_process()
  File "/usr/lib/python2.7/dist-packages/gunicorn/workers/base.py", line 100, in init_process
    self.wsgi = self.app.wsgi()
  File "/usr/lib/python2.7/dist-packages/gunicorn/app/base.py", line 115, in wsgi
    self.callable = self.load()
  File "/usr/lib/python2.7/dist-packages/gunicorn/app/wsgiapp.py", line 33, in load
    return util.import_app(self.app_uri)
  File "/usr/lib/python2.7/dist-packages/gunicorn/util.py", line 362, in import_app
    __import__(module)
ImportError: No module named hello.py
2018-11-06 16:42:56 [661] [INFO] Worker exiting (pid: 661)
2018-11-06 16:42:56 [662] [INFO] Booting worker with pid: 662
2018-11-06 16:42:57 [662] [ERROR] Exception in worker process:
Traceback (most recent call last):
  File "/usr/lib/python2.7/dist-packages/gunicorn/arbiter.py", line 473, in spawn_worker
    worker.init_process()
  File "/usr/lib/python2.7/dist-packages/gunicorn/workers/base.py", line 100, in init_process
    self.wsgi = self.app.wsgi()
  File "/usr/lib/python2.7/dist-packages/gunicorn/app/base.py", line 115, in wsgi
    self.callable = self.load()
  File "/usr/lib/python2.7/dist-packages/gunicorn/app/wsgiapp.py", line 33, in load
    return util.import_app(self.app_uri)
  File "/usr/lib/python2.7/dist-packages/gunicorn/util.py", line 362, in import_app
    __import__(module)
ImportError: No module named hello.py
Traceback (most recent call last):
  File "/usr/lib/python2.7/dist-packages/gunicorn/arbiter.py", line 473, in spawn_worker
    worker.init_process()
  File "/usr/lib/python2.7/dist-packages/gunicorn/workers/base.py", line 100, in init_process
    self.wsgi = self.app.wsgi()
  File "/usr/lib/python2.7/dist-packages/gunicorn/app/base.py", line 115, in wsgi
    self.callable = self.load()
  File "/usr/lib/python2.7/dist-packages/gunicorn/app/wsgiapp.py", line 33, in load
    return util.import_app(self.app_uri)
  File "/usr/lib/python2.7/dist-packages/gunicorn/util.py", line 362, in import_app
    __import__(module)
ImportError: No module named hello.py
2018-11-06 16:42:57 [663] [INFO] Booting worker with pid: 663
2018-11-06 16:42:57 [662] [INFO] Worker exiting (pid: 662)
2018-11-06 16:42:57 [663] [ERROR] Exception in worker process:
Traceback (most recent call last):
  File "/usr/lib/python2.7/dist-packages/gunicorn/arbiter.py", line 473, in spawn_worker
    worker.init_process()
  File "/usr/lib/python2.7/dist-packages/gunicorn/workers/base.py", line 100, in init_process
    self.wsgi = self.app.wsgi()
  File "/usr/lib/python2.7/dist-packages/gunicorn/app/base.py", line 115, in wsgi
    self.callable = self.load()
  File "/usr/lib/python2.7/dist-packages/gunicorn/app/wsgiapp.py", line 33, in load
    return util.import_app(self.app_uri)
  File "/usr/lib/python2.7/dist-packages/gunicorn/util.py", line 362, in import_app
    __import__(module)
ImportError: No module named hello.py
Traceback (most recent call last):
  File "/usr/lib/python2.7/dist-packages/gunicorn/arbiter.py", line 473, in spawn_worker
    worker.init_process()
  File "/usr/lib/python2.7/dist-packages/gunicorn/workers/base.py", line 100, in init_process
    self.wsgi = self.app.wsgi()
  File "/usr/lib/python2.7/dist-packages/gunicorn/app/base.py", line 115, in wsgi
    self.callable = self.load()
  File "/usr/lib/python2.7/dist-packages/gunicorn/app/wsgiapp.py", line 33, in load
    return util.import_app(self.app_uri)
  File "/usr/lib/python2.7/dist-packages/gunicorn/util.py", line 362, in import_app
    __import__(module)
ImportError: No module named hello.py
2018-11-06 16:42:57 [663] [INFO] Worker exiting (pid: 663)
2018-11-06 16:42:57 [664] [INFO] Booting worker with pid: 664
2018-11-06 16:42:57 [665] [INFO] Booting worker with pid: 665
2018-11-06 16:42:57 [664] [ERROR] Exception in worker process:
Traceback (most recent call last):
  File "/usr/lib/python2.7/dist-packages/gunicorn/arbiter.py", line 473, in spawn_worker
    worker.init_process()
  File "/usr/lib/python2.7/dist-packages/gunicorn/workers/base.py", line 100, in init_process
    self.wsgi = self.app.wsgi()
  File "/usr/lib/python2.7/dist-packages/gunicorn/app/base.py", line 115, in wsgi
    self.callable = self.load()
  File "/usr/lib/python2.7/dist-packages/gunicorn/app/wsgiapp.py", line 33, in load
    return util.import_app(self.app_uri)
  File "/usr/lib/python2.7/dist-packages/gunicorn/util.py", line 362, in import_app
    __import__(module)
ImportError: No module named hello.py
Traceback (most recent call last):
  File "/usr/lib/python2.7/dist-packages/gunicorn/arbiter.py", line 473, in spawn_worker
    worker.init_process()
  File "/usr/lib/python2.7/dist-packages/gunicorn/workers/base.py", line 100, in init_process
    self.wsgi = self.app.wsgi()
  File "/usr/lib/python2.7/dist-packages/gunicorn/app/base.py", line 115, in wsgi
    self.callable = self.load()
  File "/usr/lib/python2.7/dist-packages/gunicorn/app/wsgiapp.py", line 33, in load
    return util.import_app(self.app_uri)
  File "/usr/lib/python2.7/dist-packages/gunicorn/util.py", line 362, in import_app
    __import__(module)
ImportError: No module named hello.py
2018-11-06 16:42:57 [664] [INFO] Worker exiting (pid: 664)
2018-11-06 16:42:57 [665] [ERROR] Exception in worker process:
Traceback (most recent call last):
  File "/usr/lib/python2.7/dist-packages/gunicorn/arbiter.py", line 473, in spawn_worker
    worker.init_process()
  File "/usr/lib/python2.7/dist-packages/gunicorn/workers/base.py", line 100, in init_process
    self.wsgi = self.app.wsgi()
  File "/usr/lib/python2.7/dist-packages/gunicorn/app/base.py", line 115, in wsgi
    self.callable = self.load()
  File "/usr/lib/python2.7/dist-packages/gunicorn/app/wsgiapp.py", line 33, in load
    return util.import_app(self.app_uri)
  File "/usr/lib/python2.7/dist-packages/gunicorn/util.py", line 362, in import_app
    __import__(module)
ImportError: No module named hello.py
Traceback (most recent call last):
  File "/usr/lib/python2.7/dist-packages/gunicorn/arbiter.py", line 473, in spawn_worker
    worker.init_process()
  File "/usr/lib/python2.7/dist-packages/gunicorn/workers/base.py", line 100, in init_process
    self.wsgi = self.app.wsgi()
  File "/usr/lib/python2.7/dist-packages/gunicorn/app/base.py", line 115, in wsgi
    self.callable = self.load()
  File "/usr/lib/python2.7/dist-packages/gunicorn/app/wsgiapp.py", line 33, in load
    return util.import_app(self.app_uri)
  File "/usr/lib/python2.7/dist-packages/gunicorn/util.py", line 362, in import_app
    __import__(module)
ImportError: No module named hello.py
2018-11-06 16:42:57 [665] [INFO] Worker exiting (pid: 665)
Traceback (most recent call last):
  File "/usr/bin/gunicorn", line 9, in <module>
    load_entry_point('gunicorn==17.5', 'console_scripts', 'gunicorn')()
  File "/usr/lib/python2.7/dist-packages/gunicorn/app/wsgiapp.py", line 42, in run
    WSGIApplication("%(prog)s [OPTIONS] APP_MODULE").run()
  File "/usr/lib/python2.7/dist-packages/gunicorn/app/base.py", line 144, in run
    Arbiter(self).run()
  File "/usr/lib/python2.7/dist-packages/gunicorn/arbiter.py", line 196, in run
    self.halt(reason=inst.reason, exit_status=inst.exit_status)
  File "/usr/lib/python2.7/dist-packages/gunicorn/arbiter.py", line 291, in halt
    self.stop()
  File "/usr/lib/python2.7/dist-packages/gunicorn/arbiter.py", line 334, in stop
    self.reap_workers()
  File "/usr/lib/python2.7/dist-packages/gunicorn/arbiter.py", line 430, in reap_workers
    raise HaltServer(reason, self.WORKER_BOOT_ERROR)
gunicorn.errors.HaltServer: <HaltServer 'Worker failed to boot.' 3>
2018-11-06 16:44:44 [750] [INFO] Starting gunicorn 17.5
2018-11-06 16:44:44 [750] [INFO] Listening at: http://0.0.0.0:8000 (750)
2018-11-06 16:44:44 [750] [INFO] Using worker: sync
2018-11-06 16:44:44 [755] [INFO] Booting worker with pid: 755
2018-11-06 16:44:44 [756] [INFO] Booting worker with pid: 756
2018-11-06 16:44:44 [757] [INFO] Booting worker with pid: 757
2018-11-06 16:44:44 [758] [INFO] Booting worker with pid: 758
2018-11-06 16:44:44 [759] [INFO] Booting worker with pid: 759
2018-11-06 16:44:44 [760] [INFO] Booting worker with pid: 760
2018-11-06 16:44:44 [761] [INFO] Booting worker with pid: 761
2018-11-06 16:44:44 [762] [INFO] Booting worker with pid: 762
2018-11-06 16:44:44 [763] [INFO] Booting worker with pid: 763
2018-11-06 16:44:44 [764] [INFO] Booting worker with pid: 764
2018-11-06 16:44:44 [765] [INFO] Booting worker with pid: 765
2018-11-06 16:44:44 [766] [INFO] Booting worker with pid: 766
2018-11-06 16:44:44 [767] [INFO] Booting worker with pid: 767
2018-11-06 16:44:44 [768] [INFO] Booting worker with pid: 768
2018-11-06 16:44:44 [769] [INFO] Booting worker with pid: 769
2018-11-06 16:44:44 [770] [INFO] Booting worker with pid: 770
2018-11-06 16:47:24 [750] [INFO] Handling signal: term
2018-11-06 16:47:24 [768] [INFO] Worker exiting (pid: 768)
2018-11-06 16:47:24 [770] [INFO] Worker exiting (pid: 770)
2018-11-06 16:47:24 [755] [INFO] Worker exiting (pid: 755)
2018-11-06 16:47:24 [756] [INFO] Worker exiting (pid: 756)
2018-11-06 16:47:24 [760] [INFO] Worker exiting (pid: 760)
2018-11-06 16:47:24 [767] [INFO] Worker exiting (pid: 767)
2018-11-06 16:47:24 [763] [INFO] Worker exiting (pid: 763)
2018-11-06 16:47:24 [764] [INFO] Worker exiting (pid: 764)
2018-11-06 16:47:24 [766] [INFO] Worker exiting (pid: 766)
2018-11-06 16:47:24 [757] [INFO] Worker exiting (pid: 757)
2018-11-06 16:47:24 [758] [INFO] Worker exiting (pid: 758)
2018-11-06 16:47:24 [759] [INFO] Worker exiting (pid: 759)
2018-11-06 16:47:24 [761] [INFO] Worker exiting (pid: 761)
2018-11-06 16:47:24 [762] [INFO] Worker exiting (pid: 762)
2018-11-06 16:47:24 [765] [INFO] Worker exiting (pid: 765)
2018-11-06 16:47:24 [769] [INFO] Worker exiting (pid: 769)
2018-11-06 16:47:25 [750] [INFO] Shutting down: Master
2018-11-06 16:47:25 [893] [INFO] Starting gunicorn 17.5
2018-11-06 16:47:25 [893] [INFO] Listening at: http://0.0.0.0:8000 (893)
2018-11-06 16:47:25 [893] [INFO] Using worker: sync
2018-11-06 16:47:25 [898] [INFO] Booting worker with pid: 898
2018-11-06 16:47:25 [899] [INFO] Booting worker with pid: 899
2018-11-06 16:47:25 [900] [INFO] Booting worker with pid: 900
2018-11-06 16:47:25 [901] [INFO] Booting worker with pid: 901
2018-11-06 16:47:25 [902] [INFO] Booting worker with pid: 902
2018-11-06 16:47:25 [903] [INFO] Booting worker with pid: 903
2018-11-06 16:47:25 [904] [INFO] Booting worker with pid: 904
2018-11-06 16:47:25 [905] [INFO] Booting worker with pid: 905
2018-11-06 16:47:25 [906] [INFO] Booting worker with pid: 906
2018-11-06 16:47:25 [907] [INFO] Booting worker with pid: 907
2018-11-06 16:47:25 [908] [INFO] Booting worker with pid: 908
2018-11-06 16:47:25 [909] [INFO] Booting worker with pid: 909
2018-11-06 16:47:25 [910] [INFO] Booting worker with pid: 910
2018-11-06 16:47:25 [911] [INFO] Booting worker with pid: 911
2018-11-06 16:47:26 [912] [INFO] Booting worker with pid: 912
2018-11-06 16:47:26 [913] [INFO] Booting worker with pid: 913
2018-11-06 16:49:48 [893] [INFO] Handling signal: term
2018-11-06 16:49:48 [900] [INFO] Worker exiting (pid: 900)
2018-11-06 16:49:48 [903] [INFO] Worker exiting (pid: 903)
2018-11-06 16:49:48 [905] [INFO] Worker exiting (pid: 905)
2018-11-06 16:49:48 [910] [INFO] Worker exiting (pid: 910)
2018-11-06 16:49:48 [898] [INFO] Worker exiting (pid: 898)
2018-11-06 16:49:48 [899] [INFO] Worker exiting (pid: 899)
2018-11-06 16:49:48 [908] [INFO] Worker exiting (pid: 908)
2018-11-06 16:49:48 [901] [INFO] Worker exiting (pid: 901)
2018-11-06 16:49:48 [902] [INFO] Worker exiting (pid: 902)
2018-11-06 16:49:48 [904] [INFO] Worker exiting (pid: 904)
2018-11-06 16:49:48 [906] [INFO] Worker exiting (pid: 906)
2018-11-06 16:49:48 [907] [INFO] Worker exiting (pid: 907)
2018-11-06 16:49:48 [909] [INFO] Worker exiting (pid: 909)
2018-11-06 16:49:48 [911] [INFO] Worker exiting (pid: 911)
2018-11-06 16:49:48 [912] [INFO] Worker exiting (pid: 912)
2018-11-06 16:49:48 [913] [INFO] Worker exiting (pid: 913)
2018-11-06 16:49:48 [893] [INFO] Shutting down: Master
2018-11-06 16:49:49 [1028] [INFO] Starting gunicorn 17.5
2018-11-06 16:49:49 [1028] [INFO] Listening at: http://0.0.0.0:8000 (1028)
2018-11-06 16:49:49 [1028] [INFO] Using worker: sync
2018-11-06 16:49:49 [1033] [INFO] Booting worker with pid: 1033
2018-11-06 16:49:49 [1034] [INFO] Booting worker with pid: 1034
2018-11-06 16:49:49 [1035] [INFO] Booting worker with pid: 1035
2018-11-06 16:49:49 [1036] [INFO] Booting worker with pid: 1036
2018-11-06 16:49:49 [1037] [INFO] Booting worker with pid: 1037
2018-11-06 16:49:49 [1038] [INFO] Booting worker with pid: 1038
2018-11-06 16:49:49 [1039] [INFO] Booting worker with pid: 1039
2018-11-06 16:49:49 [1040] [INFO] Booting worker with pid: 1040
2018-11-06 16:49:49 [1041] [INFO] Booting worker with pid: 1041
2018-11-06 16:49:49 [1042] [INFO] Booting worker with pid: 1042
2018-11-06 16:49:49 [1043] [INFO] Booting worker with pid: 1043
2018-11-06 16:49:49 [1044] [INFO] Booting worker with pid: 1044
2018-11-06 16:49:49 [1045] [INFO] Booting worker with pid: 1045
2018-11-06 16:49:49 [1046] [INFO] Booting worker with pid: 1046
2018-11-06 16:49:49 [1047] [INFO] Booting worker with pid: 1047
2018-11-06 16:49:49 [1048] [INFO] Booting worker with pid: 1048
2018-11-06 16:49:51 [1028] [INFO] Handling signal: term
2018-11-06 16:49:51 [1034] [INFO] Worker exiting (pid: 1034)
2018-11-06 16:49:51 [1037] [INFO] Worker exiting (pid: 1037)
2018-11-06 16:49:51 [1043] [INFO] Worker exiting (pid: 1043)
2018-11-06 16:49:51 [1041] [INFO] Worker exiting (pid: 1041)
2018-11-06 16:49:51 [1038] [INFO] Worker exiting (pid: 1038)
2018-11-06 16:49:51 [1033] [INFO] Worker exiting (pid: 1033)
2018-11-06 16:49:51 [1044] [INFO] Worker exiting (pid: 1044)
2018-11-06 16:49:51 [1035] [INFO] Worker exiting (pid: 1035)
2018-11-06 16:49:51 [1036] [INFO] Worker exiting (pid: 1036)
2018-11-06 16:49:51 [1039] [INFO] Worker exiting (pid: 1039)
2018-11-06 16:49:51 [1040] [INFO] Worker exiting (pid: 1040)
2018-11-06 16:49:51 [1042] [INFO] Worker exiting (pid: 1042)
2018-11-06 16:49:51 [1045] [INFO] Worker exiting (pid: 1045)
2018-11-06 16:49:51 [1046] [INFO] Worker exiting (pid: 1046)
2018-11-06 16:49:51 [1047] [INFO] Worker exiting (pid: 1047)
2018-11-06 16:49:51 [1048] [INFO] Worker exiting (pid: 1048)
2018-11-06 16:49:51 [1028] [INFO] Shutting down: Master
2018-11-06 16:49:51 [1120] [INFO] Starting gunicorn 17.5
2018-11-06 16:49:51 [1120] [INFO] Listening at: http://0.0.0.0:8000 (1120)
2018-11-06 16:49:51 [1120] [INFO] Using worker: sync
2018-11-06 16:49:51 [1125] [INFO] Booting worker with pid: 1125
2018-11-06 16:49:51 [1126] [INFO] Booting worker with pid: 1126
2018-11-06 16:49:51 [1127] [INFO] Booting worker with pid: 1127
2018-11-06 16:49:51 [1128] [INFO] Booting worker with pid: 1128
2018-11-06 16:49:51 [1129] [INFO] Booting worker with pid: 1129
2018-11-06 16:49:51 [1130] [INFO] Booting worker with pid: 1130
2018-11-06 16:49:51 [1131] [INFO] Booting worker with pid: 1131
2018-11-06 16:49:51 [1132] [INFO] Booting worker with pid: 1132
2018-11-06 16:49:51 [1133] [INFO] Booting worker with pid: 1133
2018-11-06 16:49:51 [1134] [INFO] Booting worker with pid: 1134
2018-11-06 16:49:51 [1135] [INFO] Booting worker with pid: 1135
2018-11-06 16:49:52 [1136] [INFO] Booting worker with pid: 1136
2018-11-06 16:49:52 [1137] [INFO] Booting worker with pid: 1137
2018-11-06 16:49:52 [1138] [INFO] Booting worker with pid: 1138
2018-11-06 16:49:52 [1139] [INFO] Booting worker with pid: 1139
2018-11-06 16:49:52 [1140] [INFO] Booting worker with pid: 1140
2018-11-06 16:49:53 [1120] [INFO] Handling signal: term
2018-11-06 16:49:53 [1126] [INFO] Worker exiting (pid: 1126)
2018-11-06 16:49:53 [1135] [INFO] Worker exiting (pid: 1135)
2018-11-06 16:49:53 [1130] [INFO] Worker exiting (pid: 1130)
2018-11-06 16:49:53 [1132] [INFO] Worker exiting (pid: 1132)
2018-11-06 16:49:53 [1129] [INFO] Worker exiting (pid: 1129)
2018-11-06 16:49:53 [1125] [INFO] Worker exiting (pid: 1125)
2018-11-06 16:49:53 [1127] [INFO] Worker exiting (pid: 1127)
2018-11-06 16:49:53 [1128] [INFO] Worker exiting (pid: 1128)
2018-11-06 16:49:53 [1131] [INFO] Worker exiting (pid: 1131)
2018-11-06 16:49:53 [1133] [INFO] Worker exiting (pid: 1133)
2018-11-06 16:49:53 [1134] [INFO] Worker exiting (pid: 1134)
2018-11-06 16:49:53 [1136] [INFO] Worker exiting (pid: 1136)
2018-11-06 16:49:53 [1137] [INFO] Worker exiting (pid: 1137)
2018-11-06 16:49:53 [1138] [INFO] Worker exiting (pid: 1138)
2018-11-06 16:49:53 [1139] [INFO] Worker exiting (pid: 1139)
2018-11-06 16:49:53 [1140] [INFO] Worker exiting (pid: 1140)
2018-11-06 16:49:53 [1120] [INFO] Shutting down: Master
2018-11-06 16:49:54 [1212] [INFO] Starting gunicorn 17.5
2018-11-06 16:49:54 [1212] [INFO] Listening at: http://0.0.0.0:8000 (1212)
2018-11-06 16:49:54 [1212] [INFO] Using worker: sync
2018-11-06 16:49:54 [1217] [INFO] Booting worker with pid: 1217
2018-11-06 16:49:54 [1218] [INFO] Booting worker with pid: 1218
2018-11-06 16:49:54 [1219] [INFO] Booting worker with pid: 1219
2018-11-06 16:49:54 [1220] [INFO] Booting worker with pid: 1220
2018-11-06 16:49:54 [1221] [INFO] Booting worker with pid: 1221
2018-11-06 16:49:54 [1222] [INFO] Booting worker with pid: 1222
2018-11-06 16:49:54 [1223] [INFO] Booting worker with pid: 1223
2018-11-06 16:49:54 [1224] [INFO] Booting worker with pid: 1224
2018-11-06 16:49:54 [1225] [INFO] Booting worker with pid: 1225
2018-11-06 16:49:54 [1226] [INFO] Booting worker with pid: 1226
2018-11-06 16:49:54 [1227] [INFO] Booting worker with pid: 1227
2018-11-06 16:49:54 [1228] [INFO] Booting worker with pid: 1228
2018-11-06 16:49:54 [1229] [INFO] Booting worker with pid: 1229
2018-11-06 16:49:54 [1230] [INFO] Booting worker with pid: 1230
2018-11-06 16:49:54 [1231] [INFO] Booting worker with pid: 1231
2018-11-06 16:49:54 [1232] [INFO] Booting worker with pid: 1232
2018-11-06 16:50:12 [1212] [INFO] Handling signal: term
2018-11-06 16:50:12 [1217] [INFO] Worker exiting (pid: 1217)
2018-11-06 16:50:12 [1218] [INFO] Worker exiting (pid: 1218)
2018-11-06 16:50:12 [1219] [INFO] Worker exiting (pid: 1219)
2018-11-06 16:50:12 [1220] [INFO] Worker exiting (pid: 1220)
2018-11-06 16:50:12 [1221] [INFO] Worker exiting (pid: 1221)
2018-11-06 16:50:12 [1224] [INFO] Worker exiting (pid: 1224)
2018-11-06 16:50:12 [1225] [INFO] Worker exiting (pid: 1225)
2018-11-06 16:50:12 [1226] [INFO] Worker exiting (pid: 1226)
2018-11-06 16:50:12 [1228] [INFO] Worker exiting (pid: 1228)
2018-11-06 16:50:12 [1229] [INFO] Worker exiting (pid: 1229)
2018-11-06 16:50:12 [1230] [INFO] Worker exiting (pid: 1230)
2018-11-06 16:50:12 [1231] [INFO] Worker exiting (pid: 1231)
2018-11-06 16:50:12 [1232] [INFO] Worker exiting (pid: 1232)
2018-11-06 16:50:12 [1222] [INFO] Worker exiting (pid: 1222)
2018-11-06 16:50:12 [1223] [INFO] Worker exiting (pid: 1223)
2018-11-06 16:50:12 [1212] [INFO] Shutting down: Master
2018-11-06 16:50:12 [1305] [INFO] Starting gunicorn 17.5
2018-11-06 16:50:12 [1305] [INFO] Listening at: http://0.0.0.0:8000 (1305)
2018-11-06 16:50:12 [1305] [INFO] Using worker: sync
2018-11-06 16:50:12 [1310] [INFO] Booting worker with pid: 1310
2018-11-06 16:50:12 [1311] [INFO] Booting worker with pid: 1311
2018-11-06 16:50:13 [1312] [INFO] Booting worker with pid: 1312
2018-11-06 16:50:13 [1313] [INFO] Booting worker with pid: 1313
2018-11-06 16:50:13 [1314] [INFO] Booting worker with pid: 1314
2018-11-06 16:50:13 [1315] [INFO] Booting worker with pid: 1315
2018-11-06 16:50:13 [1316] [INFO] Booting worker with pid: 1316
2018-11-06 16:50:13 [1317] [INFO] Booting worker with pid: 1317
2018-11-06 16:50:13 [1318] [INFO] Booting worker with pid: 1318
2018-11-06 16:50:13 [1319] [INFO] Booting worker with pid: 1319
2018-11-06 16:50:13 [1320] [INFO] Booting worker with pid: 1320
2018-11-06 16:50:13 [1321] [INFO] Booting worker with pid: 1321
2018-11-06 16:50:13 [1322] [INFO] Booting worker with pid: 1322
2018-11-06 16:50:13 [1323] [INFO] Booting worker with pid: 1323
2018-11-06 16:50:13 [1324] [INFO] Booting worker with pid: 1324
2018-11-06 16:50:13 [1325] [INFO] Booting worker with pid: 1325
2018-11-06 16:50:44 [1305] [INFO] Handling signal: term
2018-11-06 16:50:44 [1312] [INFO] Worker exiting (pid: 1312)
2018-11-06 16:50:44 [1314] [INFO] Worker exiting (pid: 1314)
2018-11-06 16:50:44 [1313] [INFO] Worker exiting (pid: 1313)
2018-11-06 16:50:44 [1315] [INFO] Worker exiting (pid: 1315)
2018-11-06 16:50:44 [1317] [INFO] Worker exiting (pid: 1317)
2018-11-06 16:50:44 [1320] [INFO] Worker exiting (pid: 1320)
2018-11-06 16:50:44 [1324] [INFO] Worker exiting (pid: 1324)
2018-11-06 16:50:44 [1325] [INFO] Worker exiting (pid: 1325)
2018-11-06 16:50:44 [1311] [INFO] Worker exiting (pid: 1311)
2018-11-06 16:50:44 [1319] [INFO] Worker exiting (pid: 1319)
2018-11-06 16:50:44 [1321] [INFO] Worker exiting (pid: 1321)
2018-11-06 16:50:44 [1323] [INFO] Worker exiting (pid: 1323)
2018-11-06 16:50:44 [1316] [INFO] Worker exiting (pid: 1316)
2018-11-06 16:50:44 [1318] [INFO] Worker exiting (pid: 1318)
2018-11-06 16:50:44 [1322] [INFO] Worker exiting (pid: 1322)
2018-11-06 16:50:44 [1310] [INFO] Worker exiting (pid: 1310)
Exception SystemExit: 0 in <module 'threading' from '/usr/lib/python2.7/threading.pyc'> ignored
2018-11-06 16:50:44 [1305] [INFO] Shutting down: Master
2018-11-06 16:50:44 [1405] [INFO] Starting gunicorn 17.5
2018-11-06 16:50:44 [1405] [INFO] Listening at: http://0.0.0.0:8000 (1405)
2018-11-06 16:50:44 [1405] [INFO] Using worker: sync
2018-11-06 16:50:44 [1410] [INFO] Booting worker with pid: 1410
2018-11-06 16:50:44 [1411] [INFO] Booting worker with pid: 1411
2018-11-06 16:50:44 [1412] [INFO] Booting worker with pid: 1412
2018-11-06 16:50:44 [1413] [INFO] Booting worker with pid: 1413
2018-11-06 16:50:44 [1414] [INFO] Booting worker with pid: 1414
2018-11-06 16:50:44 [1415] [INFO] Booting worker with pid: 1415
2018-11-06 16:50:44 [1416] [INFO] Booting worker with pid: 1416
2018-11-06 16:50:44 [1417] [INFO] Booting worker with pid: 1417
2018-11-06 16:50:44 [1418] [INFO] Booting worker with pid: 1418
2018-11-06 16:50:44 [1419] [INFO] Booting worker with pid: 1419
2018-11-06 16:50:44 [1420] [INFO] Booting worker with pid: 1420
2018-11-06 16:50:44 [1421] [INFO] Booting worker with pid: 1421
2018-11-06 16:50:45 [1422] [INFO] Booting worker with pid: 1422
2018-11-06 16:50:45 [1423] [INFO] Booting worker with pid: 1423
2018-11-06 16:50:45 [1424] [INFO] Booting worker with pid: 1424
2018-11-06 16:50:45 [1425] [INFO] Booting worker with pid: 1425
2018-11-06 16:58:58 [1405] [INFO] Handling signal: term
2018-11-06 16:58:58 [1411] [INFO] Worker exiting (pid: 1411)
2018-11-06 16:58:58 [1410] [INFO] Worker exiting (pid: 1410)
2018-11-06 16:58:58 [1415] [INFO] Worker exiting (pid: 1415)
2018-11-06 16:58:58 [1412] [INFO] Worker exiting (pid: 1412)
2018-11-06 16:58:58 [1418] [INFO] Worker exiting (pid: 1418)
2018-11-06 16:58:58 [1413] [INFO] Worker exiting (pid: 1413)
2018-11-06 16:58:58 [1419] [INFO] Worker exiting (pid: 1419)
2018-11-06 16:58:58 [1414] [INFO] Worker exiting (pid: 1414)
2018-11-06 16:58:58 [1421] [INFO] Worker exiting (pid: 1421)
2018-11-06 16:58:58 [1417] [INFO] Worker exiting (pid: 1417)
2018-11-06 16:58:58 [1422] [INFO] Worker exiting (pid: 1422)
2018-11-06 16:58:58 [1420] [INFO] Worker exiting (pid: 1420)
2018-11-06 16:58:58 [1423] [INFO] Worker exiting (pid: 1423)
2018-11-06 16:58:58 [1424] [INFO] Worker exiting (pid: 1424)
2018-11-06 16:58:58 [1425] [INFO] Worker exiting (pid: 1425)
2018-11-06 16:58:58 [1416] [INFO] Worker exiting (pid: 1416)
2018-11-06 16:58:59 [1405] [INFO] Shutting down: Master
